Workbook

Sheet Read me
A1: In questo file sono raccolti i dati di incentivi annuali per pompe di calore per Cantone. Il programma di incentivazione per gli edifici varia da cantone a cantone, ma sono tutti sotto il cappello del Programma Edifici: https://www.ilprogrammaedifici.ch/it/ In questo programma, i proventi della tassa sulla CO2 vengono ridistribuiti ai vari cantoni; sono poi i cantoni a decidere gli incentivi per i singoli interventi di risanamento energetico. Dal 2017 in poi i dati sugli incentivi concesssi sono stati suddivisi anche per tipo di edificio (SFH - MFH - NonResidenziale). Qui si trovano i rapporti del Programma Edifici con tutti i dati: https://www.ilprogrammaedifici.ch/it/meta/pubblicazioni-e-foto/rapporti-e-statistiche/ Nel foglio "Total" sono raccolti i dati cumulati, si potrebbe usare un incentivo medio per cantone per tipo di edificio per l'analisi di regressione.
A2: I cantoni hanno delle linee guida da seguire per legiferare in materia di consumi energetici, che sono decise dalla Conferenza dei direttori cantonali dell'energia: https://endk.ch/it/ Questo direttorio produce delle linee guida ogni tot anni. L'ultima linea guida approvata è il MuKen (MoPEC) 2025. prima di esso, erano repsenti le linee guida del MoPEC 2014: https://edificiopoloenergia.ch/politica-energetica-dei-cantoni/#mopec-2014 Oltre a dare delle linee guida sugli interventi da finanziare, nel MoPEC 2014 ci sono anche linee guida su leggi da applicare. Due sono interessanti: - Art. 1.29 --> obbligo di avere almeno parte della produzione di calore da fonti rinnovabili se si sostituisce l'attuale sistema di rscaldamento. - Art. 1.26 --> obbligo di produzione autonoma di elettricità (PV) nei nuovi edifici. L'applicazione o meno di queste linee guida nei vari cantoni sono raccolte nel documento "Stato della politica energetica nei cantoni" (https://edificiopoloenergia.ch/politica-energetica-dei-cantoni/) e i dati sono raccolti nella pagina "applicazione MoPEC" in questo file.

Sheet Total
A1: Index | B1: HP - SFH - MoPEC 2015 - CHF | C1: AG | D1: AI | E1: AR | F1: BE | G1: BL | H1: BS | I1: FR | J1: GE | K1: GL | L1: GR | M1: JU | N1: LU | O1: NE | P1: NW | Q1: OW | R1: SG | S1: SH | T1: SO | U1: SZ | V1: TG | W1: TI | X1: UR | Y1: VD | Z1: VS | AA1: ZG | AB1: ZH | AE1: HP - SFH - MoPEC 2015 - CHF | AF1: AG | AG1: AI | AH1: AR | AI1: BE | AJ1: BL | AK1: BS | AL1: FR | AM1: GE | AN1: GL | AO1: GR | AP1: JU | AQ1: LU | AR1: NE | AS1: NW | AT1: OW | AU1: SG | AV1: SH | AW1: SO | AX1: SZ | AY1: TG | AZ1: TI | BA1: UR | BB1: VD | BC1: VS | BD1: ZG | BE1: ZH | BF1: Average
B2: 2024 | C2: =HLOOKUP(C1,'2024 CHF'!$D$57:$AC$73,$A$3,FALSE) -> 6928.618 | D2: =HLOOKUP(D1,'2024 CHF'!$D$57:$AC$73,$A$3,FALSE) -> 111.354 | E2: =HLOOKUP(E1,'2024 CHF'!$D$57:$AC$73,$A$3,FALSE) -> 1177.385 | F2: =HLOOKUP(F1,'2024 CHF'!$D$57:$AC$73,$A$3,FALSE) -> 14599.9 | G2: =HLOOKUP(G1,'2024 CHF'!$D$57:$AC$73,$A$3,FALSE) -> 8544.219 | H2: =HLOOKUP(H1,'2024 CHF'!$D$57:$AC$73,$A$3,FALSE) -> 7571.06 | I2: =HLOOKUP(I1,'2024 CHF'!$D$57:$AC$73,$A$3,FALSE) -> 6032.713 | J2: =HLOOKUP(J1,'2024 CHF'!$D$57:$AC$73,$A$3,FALSE) -> 4517.067 | ... AB2: =HLOOKUP(AB1,'2024 CHF'!$D$57:$AC$73,$A$3,FALSE) -> 20413.062 | AC2: =SUM(C2:AB2) -> 132277.27 | AE2: 2024 | AF2: =IF(C24,C2/C24,0)*1000 -> 4287.5111 | AG2: =IF(D24,D2/D24,0)*1000 -> 3093.1667 | AH2: =IF(E24,E2/E24,0)*1000 -> 5886.925 | AI2: =IF(F24,F2/F24,0)*1000 -> 6939.116 | AJ2: =IF(G24,G2/G24,0)*1000 -> 8772.2988 | AK2: =IF(H24,H2/H24,0)*1000 -> 20573.533 | AL2: =IF(I24,I2/I24,0)*1000 -> 7242.1525 | AM2: =IF(J24,J2/J24,0)*1000 -> 7158.5848 | ... BF2: =IF(AC24,AC2/AC24,0)*1000 -> 7450.9812
A3: 15 | B3: 2023 | C3: =HLOOKUP(C1,'2023 CHF'!$D$57:$AC$73,$A$3,FALSE) -> 8968.166 | D3: =HLOOKUP(D1,'2023 CHF'!$D$57:$AC$73,$A$3,FALSE) -> 107.928 | E3: =HLOOKUP(E1,'2023 CHF'!$D$57:$AC$73,$A$3,FALSE) -> 1574.441 | F3: =HLOOKUP(F1,'2023 CHF'!$D$57:$AC$73,$A$3,FALSE) -> 18476.165 | G3: =HLOOKUP(G1,'2023 CHF'!$D$57:$AC$73,$A$3,FALSE) -> 10262.988 | H3: =HLOOKUP(H1,'2023 CHF'!$D$57:$AC$73,$A$3,FALSE) -> 4854.997 | I3: =HLOOKUP(I1,'2023 CHF'!$D$57:$AC$73,$A$3,FALSE) -> 8417.26 | J3: =HLOOKUP(J1,'2023 CHF'!$D$57:$AC$73,$A$3,FALSE) -> 3309.456 | ... AB3: =HLOOKUP(AB1,'2023 CHF'!$D$57:$AC$73,$A$3,FALSE) -> 17895.123 | AC3: =SUM(C3:AB3) -> 143058.8 | AE3: 2023 | AF3: =IF(C25,C3/C25,0)*1000 -> 4987.8565 | AG3: =IF(D25,D3/D25,0)*1000 -> 3083.6571 | AH3: =IF(E25,E3/E25,0)*1000 -> 5874.7799 | AI3: =IF(F25,F3/F25,0)*1000 -> 7186.373 | AJ3: =IF(G25,G3/G25,0)*1000 -> 8269.9339 | AK3: =IF(H25,H3/H25,0)*1000 -> 17654.535 | AL3: =IF(I25,I3/I25,0)*1000 -> 7888.716 | AM3: =IF(J25,J3/J25,0)*1000 -> 7225.8865 | ... BF3: =IF(AC25,AC3/AC25,0)*1000 -> 7165.1207
B4: 2022 | C4: =HLOOKUP(C1,'2022 CHF'!$D$57:$AC$73,$A$3,FALSE) -> 5620.064 | D4: =HLOOKUP(D1,'2022 CHF'!$D$57:$AC$73,$A$3,FALSE) -> 101.242 | E4: =HLOOKUP(E1,'2022 CHF'!$D$57:$AC$73,$A$3,FALSE) -> 524.457 | F4: =HLOOKUP(F1,'2022 CHF'!$D$57:$AC$73,$A$3,FALSE) -> 17199.088 | G4: =HLOOKUP(G1,'2022 CHF'!$D$57:$AC$73,$A$3,FALSE) -> 7010.605 | H4: =HLOOKUP(H1,'2022 CHF'!$D$57:$AC$73,$A$3,FALSE) -> 2023.71 | I4: =HLOOKUP(I1,'2022 CHF'!$D$57:$AC$73,$A$3,FALSE) -> 8492.528 | J4: =HLOOKUP(J1,'2022 CHF'!$D$57:$AC$73,$A$3,FALSE) -> 1701.62 | ... AB4: =HLOOKUP(AB1,'2022 CHF'!$D$57:$AC$73,$A$3,FALSE) -> 13363.682 | AC4: =SUM(C4:AB4) -> 92251.038 | AE4: 2022 | AF4: =IF(C26,C4/C26,0)*1000 -> 5099.8766 | AG4: =IF(D26,D4/D26,0)*1000 -> 3265.871 | AH4: =IF(E26,E4/E26,0)*1000 -> 6028.2414 | AI4: =IF(F26,F4/F26,0)*1000 -> 8582.3792 | AJ4: =IF(G26,G4/G26,0)*1000 -> 8365.8771 | AK4: =IF(H26,H4/H26,0)*1000 -> 16864.25 | AL4: =IF(I26,I4/I26,0)*1000 -> 9817.9514 | AM4: =IF(J26,J4/J26,0)*1000 -> 7119.749 | ... BF4: =IF(AC26,AC4/AC26,0)*1000 -> 7222.347
B5: 2021 | C5: =HLOOKUP(C1,'2021 CHF'!$D$57:$AC$73,$A$3,FALSE) -> 1162.903 | D5: =HLOOKUP(D1,'2021 CHF'!$D$57:$AC$73,$A$3,FALSE) -> 18.701 | E5: =HLOOKUP(E1,'2021 CHF'!$D$57:$AC$73,$A$3,FALSE) -> 257.504 | F5: =HLOOKUP(F1,'2021 CHF'!$D$57:$AC$73,$A$3,FALSE) -> 19677.383 | G5: =HLOOKUP(G1,'2021 CHF'!$D$57:$AC$73,$A$3,FALSE) -> 4939.213 | H5: =HLOOKUP(H1,'2021 CHF'!$D$57:$AC$73,$A$3,FALSE) -> 2087.078 | I5: =HLOOKUP(I1,'2021 CHF'!$D$57:$AC$73,$A$3,FALSE) -> 4092.959 | J5: =HLOOKUP(J1,'2021 CHF'!$D$57:$AC$73,$A$3,FALSE) -> 1486.228 | ... AB5: =HLOOKUP(AB1,'2021 CHF'!$D$57:$AC$73,$A$3,FALSE) -> 7683.959 | AC5: =SUM(C5:AB5) -> 67919.188 | AE5: 2021 | AF5: =IF(C27,C5/C27,0)*1000 -> 5145.5885 | AG5: =IF(D27,D5/D27,0)*1000 -> 2671.5714 | AH5: =IF(E27,E5/E27,0)*1000 -> 6131.0476 | AI5: =IF(F27,F5/F27,0)*1000 -> 10296.904 | AJ5: =IF(G27,G5/G27,0)*1000 -> 8245.7646 | AK5: =IF(H27,H5/H27,0)*1000 -> 16968.114 | AL5: =IF(I27,I5/I27,0)*1000 -> 8474.0352 | AM5: =IF(J27,J5/J27,0)*1000 -> 7781.2984 | ... BF5: =IF(AC27,AC5/AC27,0)*1000 -> 7409.9049
B6: 2020 | C6: =HLOOKUP(C1,'2020 CHF'!$D$57:$AC$73,$A$3,FALSE) -> 0 | D6: =HLOOKUP(D1,'2020 CHF'!$D$57:$AC$73,$A$3,FALSE) -> 59.504 | E6: =HLOOKUP(E1,'2020 CHF'!$D$57:$AC$73,$A$3,FALSE) -> 143.258 | F6: =HLOOKUP(F1,'2020 CHF'!$D$57:$AC$73,$A$3,FALSE) -> 10206.313 | G6: =HLOOKUP(G1,'2020 CHF'!$D$57:$AC$73,$A$3,FALSE) -> 807.984 | H6: =HLOOKUP(H1,'2020 CHF'!$D$57:$AC$73,$A$3,FALSE) -> 1246.462 | I6: =HLOOKUP(I1,'2020 CHF'!$D$57:$AC$73,$A$3,FALSE) -> 2453.5045 | J6: =HLOOKUP(J1,'2020 CHF'!$D$57:$AC$73,$A$3,FALSE) -> 976.729 | ... AB6: =HLOOKUP(AB1,'2020 CHF'!$D$57:$AC$73,$A$3,FALSE) -> 537.836 | AC6: =SUM(C6:AB6) -> 33871.896 | AE6: 2020 | AF6: =IF(C28,C6/C28,0)*1000 -> 0 | AG6: =IF(D28,D6/D28,0)*1000 -> 2704.7273 | AH6: =IF(E28,E6/E28,0)*1000 -> 5116.3571 | AI6: =IF(F28,F6/F28,0)*1000 -> 9637.6893 | AJ6: =IF(G28,G6/G28,0)*1000 -> 6733.2 | AK6: =IF(H28,H6/H28,0)*1000 -> 15580.775 | AL6: =IF(I28,I6/I28,0)*1000 -> 7132.2805 | AM6: =IF(J28,J6/J28,0)*1000 -> 8005.9754 | ... BF6: =IF(AC28,AC6/AC28,0)*1000 -> 7077.2871
B7: 2019 | C7: =HLOOKUP(C1,'2019 CHF'!$D$57:$AC$73,$A$3,FALSE) -> 0 | D7: =HLOOKUP(D1,'2019 CHF'!$D$57:$AC$73,$A$3,FALSE) -> 55.096 | E7: =HLOOKUP(E1,'2019 CHF'!$D$57:$AC$73,$A$3,FALSE) -> 56.52 | F7: =HLOOKUP(F1,'2019 CHF'!$D$57:$AC$73,$A$3,FALSE) -> 2530.13 | G7: =HLOOKUP(G1,'2019 CHF'!$D$57:$AC$73,$A$3,FALSE) -> 147.878 | H7: =HLOOKUP(H1,'2019 CHF'!$D$57:$AC$73,$A$3,FALSE) -> 340.977 | I7: =HLOOKUP(I1,'2019 CHF'!$D$57:$AC$73,$A$3,FALSE) -> 1570.4445 | J7: =HLOOKUP(J1,'2019 CHF'!$D$57:$AC$73,$A$3,FALSE) -> 967.519 | ... AB7: =HLOOKUP(AB1,'2019 CHF'!$D$57:$AC$73,$A$3,FALSE) -> 0 | AC7: =SUM(C7:AB7) -> 16038.371 | AE7: 2019 | AF7: =IF(C29,C7/C29,0)*1000 -> 0 | AG7: =IF(D29,D7/D29,0)*1000 -> 3240.9412 | AH7: =IF(E29,E7/E29,0)*1000 -> 3768 | AI7: =IF(F29,F7/F29,0)*1000 -> 5698.491 | AJ7: =IF(G29,G7/G29,0)*1000 -> 3996.7027 | AK7: =IF(H29,H7/H29,0)*1000 -> 12628.778 | AL7: =IF(I29,I7/I29,0)*1000 -> 6979.7533 | AM7: =IF(J29,J7/J29,0)*1000 -> 7866.0081 | ... BF7: =IF(AC29,AC7/AC29,0)*1000 -> 6223.6595
B8: 2018 | C8: =HLOOKUP(C1,'2018 CHF'!$D$57:$AC$73,$A$3,FALSE) -> 0 | D8: =HLOOKUP(D1,'2018 CHF'!$D$57:$AC$73,$A$3,FALSE) -> 21.928 | E8: =HLOOKUP(E1,'2018 CHF'!$D$57:$AC$73,$A$3,FALSE) -> 70.69 | F8: =HLOOKUP(F1,'2018 CHF'!$D$57:$AC$73,$A$3,FALSE) -> 1704.3 | G8: =HLOOKUP(G1,'2018 CHF'!$D$57:$AC$73,$A$3,FALSE) -> 172.998 | H8: =HLOOKUP(H1,'2018 CHF'!$D$57:$AC$73,$A$3,FALSE) -> 129.8 | I8: =HLOOKUP(I1,'2018 CHF'!$D$57:$AC$73,$A$3,FALSE) -> 1296.8545 | J8: =HLOOKUP(J1,'2018 CHF'!$D$57:$AC$73,$A$3,FALSE) -> 563.668 | ... AB8: =HLOOKUP(AB1,'2018 CHF'!$D$57:$AC$73,$A$3,FALSE) -> 0 | AC8: =SUM(C8:AB8) -> 10015.822 | AE8: 2018 | AF8: =IF(C30,C8/C30,0)*1000 -> 0 | AG8: =IF(D30,D8/D30,0)*1000 -> 3132.5714 | AH8: =IF(E30,E8/E30,0)*1000 -> 4712.6667 | AI8: =IF(F30,F8/F30,0)*1000 -> 5133.4337 | AJ8: =IF(G30,G8/G30,0)*1000 -> 4119 | AK8: =IF(H30,H8/H30,0)*1000 -> 14422.222 | AL8: =IF(I30,I8/I30,0)*1000 -> 7048.1223 | AM8: =IF(J30,J8/J30,0)*1000 -> 7320.3636 | ... BF8: =IF(AC30,AC8/AC30,0)*1000 -> 5947.6375
B9: 2017 | C9: =HLOOKUP(C1,'2017 CHF'!$D$57:$AC$73,$A$3,FALSE) -> 0 | D9: =HLOOKUP(D1,'2017 CHF'!$D$57:$AC$73,$A$3,FALSE) -> 0 | E9: =HLOOKUP(E1,'2017 CHF'!$D$57:$AC$73,$A$3,FALSE) -> 0 | F9: =HLOOKUP(F1,'2017 CHF'!$D$57:$AC$73,$A$3,FALSE) -> 397.06 | G9: =HLOOKUP(G1,'2017 CHF'!$D$57:$AC$73,$A$3,FALSE) -> 23.046 | H9: =HLOOKUP(H1,'2017 CHF'!$D$57:$AC$73,$A$3,FALSE) -> 0 | I9: =HLOOKUP(I1,'2017 CHF'!$D$57:$AC$73,$A$3,FALSE) -> 143.0425 | J9: =HLOOKUP(J1,'2017 CHF'!$D$57:$AC$73,$A$3,FALSE) -> 581.844 | ... AB9: =HLOOKUP(AB1,'2017 CHF'!$D$57:$AC$73,$A$3,FALSE) -> 0 | AC9: =SUM(C9:AB9) -> 2051.5745 | AE9: 2017 | AF9: =IF(C31,C9/C31,0)*1000 -> 0 | AG9: =IF(D31,D9/D31,0)*1000 -> 0 | AH9: =IF(E31,E9/E31,0)*1000 -> 0 | AI9: =IF(F31,F9/F31,0)*1000 -> 4783.8554 | AJ9: =IF(G31,G9/G31,0)*1000 -> 3292.2857 | AK9: =IF(H31,H9/H31,0)*1000 -> 0 | AL9: =IF(I31,I9/I31,0)*1000 -> 7528.5526 | AM9: =IF(J31,J9/J31,0)*1000 -> 7862.7568 | ... BF9: =IF(AC31,AC9/AC31,0)*1000 -> 5844.9416
AE10: Average | AF10: =SUM(C2:C9)/SUM(C24:C31)*1000 -> 4782.7396 | AG10: =SUM(D2:D9)/SUM(D24:D31)*1000 -> 3069.3742 | AH10: =SUM(E2:E9)/SUM(E24:E31)*1000 -> 5808.0229 | AI10: =SUM(F2:F9)/SUM(F24:F31)*1000 -> 8069.1225 | AJ10: =SUM(G2:G9)/SUM(G24:G31)*1000 -> 8270.8478 | AK10: =SUM(H2:H9)/SUM(H24:H31)*1000 -> 18217.649 | AL10: =SUM(I2:I9)/SUM(I24:I31)*1000 -> 8084.4045 | AM10: =SUM(J2:J9)/SUM(J24:J31)*1000 -> 7365.0815 | ... BE10: =SUM(AB2:AB9)/SUM(AB24:AB31)*1000 -> 7096.4055 | BF10: =SUM(C2:AB9)/SUM(C24:AB31)*1000 -> 7204.0656
A12: Index | B12: HP - MFH - MoPEC 2015 - CHF | C12: AG | D12: AI | E12: AR | F12: BE | G12: BL | H12: BS | I12: FR | J12: GE | K12: GL | L12: GR | M12: JU | N12: LU | O12: NE | P12: NW | Q12: OW | R12: SG | S12: SH | T12: SO | U12: SZ | V12: TG | W12: TI | X12: UR | Y12: VD | Z12: VS | AA12: ZG | AB12: ZH | AE12: HP - SFH - MoPEC 2015 - CHF | AF12: AG | AG12: AI | AH12: AR | AI12: BE | AJ12: BL | AK12: BS | AL12: FR | AM12: GE | AN12: GL | AO12: GR | AP12: JU | AQ12: LU | AR12: NE | AS12: NW | AT12: OW | AU12: SG | AV12: SH | AW12: SO | AX12: SZ | AY12: TG | AZ12: TI | BA12: UR | BB12: VD | BC12: VS | BD12: ZG | BE12: ZH | BF12: Average
B13: 2024 | C13: =HLOOKUP(C12,'2024 CHF'!$D$57:$AC$73,$A$14,FALSE) -> 1885.166 | D13: =HLOOKUP(D12,'2024 CHF'!$D$57:$AC$73,$A$14,FALSE) -> 11.986 | E13: =HLOOKUP(E12,'2024 CHF'!$D$57:$AC$73,$A$14,FALSE) -> 216.652 | F13: =HLOOKUP(F12,'2024 CHF'!$D$57:$AC$73,$A$14,FALSE) -> 3690.81 | G13: =HLOOKUP(G12,'2024 CHF'!$D$57:$AC$73,$A$14,FALSE) -> 1468.231 | H13: =HLOOKUP(H12,'2024 CHF'!$D$57:$AC$73,$A$14,FALSE) -> 1181.99 | I13: =HLOOKUP(I12,'2024 CHF'!$D$57:$AC$73,$A$14,FALSE) -> 1194.598 | J13: =HLOOKUP(J12,'2024 CHF'!$D$57:$AC$73,$A$14,FALSE) -> 402.52 | ... AB13: =HLOOKUP(AB12,'2024 CHF'!$D$57:$AC$73,$A$14,FALSE) -> 8915.355 | AC13: =SUM(C13:AB13) -> 43310.001 | AE13: 2024 | AF13: =IF(C35,C13/C35,0)*1000 -> 7034.2015 | AG13: =IF(D35,D13/D35,0)*1000 -> 5993 | AH13: =IF(E35,E13/E35,0)*1000 -> 6770.375 | AI13: =IF(F35,F13/F35,0)*1000 -> 7852.7872 | AJ13: =IF(G35,G13/G35,0)*1000 -> 11652.627 | AK13: =IF(H35,H13/H35,0)*1000 -> 22730.577 | AL13: =IF(I35,I13/I35,0)*1000 -> 11827.703 | AM13: =IF(J35,J13/J35,0)*1000 -> 16100.8 | ... BF13: =IF(AC35,AC13/AC35,0)*1000 -> 12448.98
A14: 16 | B14: 2023 | C14: =HLOOKUP(C12,'2023 CHF'!$D$57:$AC$73,$A$14,FALSE) -> 1348.656 | D14: =HLOOKUP(D12,'2023 CHF'!$D$57:$AC$73,$A$14,FALSE) -> 21.125 | E14: =HLOOKUP(E12,'2023 CHF'!$D$57:$AC$73,$A$14,FALSE) -> 102.407 | F14: =HLOOKUP(F12,'2023 CHF'!$D$57:$AC$73,$A$14,FALSE) -> 3619.77 | G14: =HLOOKUP(G12,'2023 CHF'!$D$57:$AC$73,$A$14,FALSE) -> 1150.492 | H14: =HLOOKUP(H12,'2023 CHF'!$D$57:$AC$73,$A$14,FALSE) -> 598.192 | I14: =HLOOKUP(I12,'2023 CHF'!$D$57:$AC$73,$A$14,FALSE) -> 1202.131 | J14: =HLOOKUP(J12,'2023 CHF'!$D$57:$AC$73,$A$14,FALSE) -> 87.361 | ... AB14: =HLOOKUP(AB12,'2023 CHF'!$D$57:$AC$73,$A$14,FALSE) -> 5773.247 | AC14: =SUM(C14:AB14) -> 31387.551 | AE14: 2023 | AF14: =IF(C36,C14/C36,0)*1000 -> 6643.6256 | AG14: =IF(D36,D14/D36,0)*1000 -> 3017.8571 | AH14: =IF(E36,E14/E36,0)*1000 -> 6400.4375 | AI14: =IF(F36,F14/F36,0)*1000 -> 8043.9333 | AJ14: =IF(G36,G14/G36,0)*1000 -> 10004.278 | AK14: =IF(H36,H14/H36,0)*1000 -> 18693.5 | AL14: =IF(I36,I14/I36,0)*1000 -> 10928.464 | AM14: =IF(J36,J14/J36,0)*1000 -> 10920.125 | ... BF14: =IF(AC36,AC14/AC36,0)*1000 -> 11110.638
B15: 2022 | C15: =HLOOKUP(C12,'2022 CHF'!$D$57:$AC$73,$A$14,FALSE) -> 874.958 | D15: =HLOOKUP(D12,'2022 CHF'!$D$57:$AC$73,$A$14,FALSE) -> 21.03 | E15: =HLOOKUP(E12,'2022 CHF'!$D$57:$AC$73,$A$14,FALSE) -> 35.07 | F15: =HLOOKUP(F12,'2022 CHF'!$D$57:$AC$73,$A$14,FALSE) -> 2537.631 | G15: =HLOOKUP(G12,'2022 CHF'!$D$57:$AC$73,$A$14,FALSE) -> 787.702 | H15: =HLOOKUP(H12,'2022 CHF'!$D$57:$AC$73,$A$14,FALSE) -> 435.135 | I15: =HLOOKUP(I12,'2022 CHF'!$D$57:$AC$73,$A$14,FALSE) -> 1094.015 | J15: =HLOOKUP(J12,'2022 CHF'!$D$57:$AC$73,$A$14,FALSE) -> 54.76 | ... AB15: =HLOOKUP(AB12,'2022 CHF'!$D$57:$AC$73,$A$14,FALSE) -> 4012.583 | AC15: =SUM(C15:AB15) -> 18841.013 | AE15: 2022 | AF15: =IF(C37,C15/C37,0)*1000 -> 8101.463 | AG15: =IF(D37,D15/D37,0)*1000 -> 5257.5 | AH15: =IF(E37,E15/E37,0)*1000 -> 5845 | AI15: =IF(F37,F15/F37,0)*1000 -> 9295.3516 | AJ15: =IF(G37,G15/G37,0)*1000 -> 10940.306 | AK15: =IF(H37,H15/H37,0)*1000 -> 20720.714 | AL15: =IF(I37,I15/I37,0)*1000 -> 13675.188 | AM15: =IF(J37,J15/J37,0)*1000 -> 18253.333 | ... BF15: =IF(AC37,AC15/AC37,0)*1000 -> 10686.905
B16: 2021 | C16: =HLOOKUP(C12,'2021 CHF'!$D$57:$AC$73,$A$14,FALSE) -> 301.221 | D16: =HLOOKUP(D12,'2021 CHF'!$D$57:$AC$73,$A$14,FALSE) -> 59.064 | E16: =HLOOKUP(E12,'2021 CHF'!$D$57:$AC$73,$A$14,FALSE) -> 45.054 | F16: =HLOOKUP(F12,'2021 CHF'!$D$57:$AC$73,$A$14,FALSE) -> 2935.93 | G16: =HLOOKUP(G12,'2021 CHF'!$D$57:$AC$73,$A$14,FALSE) -> 457.617 | H16: =HLOOKUP(H12,'2021 CHF'!$D$57:$AC$73,$A$14,FALSE) -> 464.641 | I16: =HLOOKUP(I12,'2021 CHF'!$D$57:$AC$73,$A$14,FALSE) -> 699.996 | J16: =HLOOKUP(J12,'2021 CHF'!$D$57:$AC$73,$A$14,FALSE) -> 19.928 | ... AB16: =HLOOKUP(AB12,'2021 CHF'!$D$57:$AC$73,$A$14,FALSE) -> 2417.031 | AC16: =SUM(C16:AB16) -> 13499.738 | AE16: 2021 | AF16: =IF(C38,C16/C38,0)*1000 -> 7926.8684 | AG16: =IF(D38,D16/D38,0)*1000 -> 14766 | AH16: =IF(E38,E16/E38,0)*1000 -> 5631.75 | AI16: =IF(F38,F16/F38,0)*1000 -> 10337.782 | AJ16: =IF(G38,G16/G38,0)*1000 -> 9533.6875 | AK16: =IF(H38,H16/H38,0)*1000 -> 17208.926 | AL16: =IF(I38,I16/I38,0)*1000 -> 11666.6 | AM16: =IF(J38,J16/J38,0)*1000 -> 9964 | ... BF16: =IF(AC38,AC16/AC38,0)*1000 -> 10273.773
B17: 2020 | C17: =HLOOKUP(C12,'2020 CHF'!$D$57:$AC$73,$A$14,FALSE) -> 0 | D17: =HLOOKUP(D12,'2020 CHF'!$D$57:$AC$73,$A$14,FALSE) -> 17.163 | E17: =HLOOKUP(E12,'2020 CHF'!$D$57:$AC$73,$A$14,FALSE) -> 34.425 | F17: =HLOOKUP(F12,'2020 CHF'!$D$57:$AC$73,$A$14,FALSE) -> 1541.53 | G17: =HLOOKUP(G12,'2020 CHF'!$D$57:$AC$73,$A$14,FALSE) -> 96.337 | H17: =HLOOKUP(H12,'2020 CHF'!$D$57:$AC$73,$A$14,FALSE) -> 207.438 | I17: =HLOOKUP(I12,'2020 CHF'!$D$57:$AC$73,$A$14,FALSE) -> 398.64 | J17: =HLOOKUP(J12,'2020 CHF'!$D$57:$AC$73,$A$14,FALSE) -> 25 | ... AB17: =HLOOKUP(AB12,'2020 CHF'!$D$57:$AC$73,$A$14,FALSE) -> 419.611 | AC17: =SUM(C17:AB17) -> 7533.806 | AE17: 2020 | AF17: =IF(C39,C17/C39,0)*1000 -> 0 | AG17: =IF(D39,D17/D39,0)*1000 -> 5721 | AH17: =IF(E39,E17/E39,0)*1000 -> 11475 | AI17: =IF(F39,F17/F39,0)*1000 -> 9634.5625 | AJ17: =IF(G39,G17/G39,0)*1000 -> 8757.9091 | AK17: =IF(H39,H17/H39,0)*1000 -> 18858 | AL17: =IF(I39,I17/I39,0)*1000 -> 9966 | AM17: =IF(J39,J17/J39,0)*1000 -> 25000 | ... BF17: =IF(AC39,AC17/AC39,0)*1000 -> 10492.766
B18: 2019 | C18: =HLOOKUP(C12,'2019 CHF'!$D$57:$AC$73,$A$14,FALSE) -> 0 | D18: =HLOOKUP(D12,'2019 CHF'!$D$57:$AC$73,$A$14,FALSE) -> 19.014 | E18: =HLOOKUP(E12,'2019 CHF'!$D$57:$AC$73,$A$14,FALSE) -> 34.977 | F18: =HLOOKUP(F12,'2019 CHF'!$D$57:$AC$73,$A$14,FALSE) -> 452.17 | G18: =HLOOKUP(G12,'2019 CHF'!$D$57:$AC$73,$A$14,FALSE) -> 2.8 | H18: =HLOOKUP(H12,'2019 CHF'!$D$57:$AC$73,$A$14,FALSE) -> 97.138 | I18: =HLOOKUP(I12,'2019 CHF'!$D$57:$AC$73,$A$14,FALSE) -> 220.048 | J18: =HLOOKUP(J12,'2019 CHF'!$D$57:$AC$73,$A$14,FALSE) -> 10.14 | ... AB18: =HLOOKUP(AB12,'2019 CHF'!$D$57:$AC$73,$A$14,FALSE) -> 0 | AC18: =SUM(C18:AB18) -> 2899.0803 | AE18: 2019 | AF18: =IF(C40,C18/C40,0)*1000 -> 0 | AG18: =IF(D40,D18/D40,0)*1000 -> 4753.5 | AH18: =IF(E40,E18/E40,0)*1000 -> 8744.25 | AI18: =IF(F40,F18/F40,0)*1000 -> 6956.4615 | AJ18: =IF(G40,G18/G40,0)*1000 -> 2800 | AK18: =IF(H40,H18/H40,0)*1000 -> 24284.5 | AL18: =IF(I40,I18/I40,0)*1000 -> 9567.3043 | AM18: =IF(J40,J18/J40,0)*1000 -> 10140 | ... BF18: =IF(AC40,AC18/AC40,0)*1000 -> 8403.1314
B19: 2018 | C19: =HLOOKUP(C12,'2018 CHF'!$D$57:$AC$73,$A$14,FALSE) -> 0 | D19: =HLOOKUP(D12,'2018 CHF'!$D$57:$AC$73,$A$14,FALSE) -> 18.788 | E19: =HLOOKUP(E12,'2018 CHF'!$D$57:$AC$73,$A$14,FALSE) -> 35.574 | F19: =HLOOKUP(F12,'2018 CHF'!$D$57:$AC$73,$A$14,FALSE) -> 357.67 | G19: =HLOOKUP(G12,'2018 CHF'!$D$57:$AC$73,$A$14,FALSE) -> 3.48 | H19: =HLOOKUP(H12,'2018 CHF'!$D$57:$AC$73,$A$14,FALSE) -> 14.025 | I19: =HLOOKUP(I12,'2018 CHF'!$D$57:$AC$73,$A$14,FALSE) -> 64.5345 | J19: =HLOOKUP(J12,'2018 CHF'!$D$57:$AC$73,$A$14,FALSE) -> 0 | ... AB19: =HLOOKUP(AB12,'2018 CHF'!$D$57:$AC$73,$A$14,FALSE) -> 0 | AC19: =SUM(C19:AB19) -> 1609.8907 | AE19: 2018 | AF19: =IF(C41,C19/C41,0)*1000 -> 0 | AG19: =IF(D41,D19/D41,0)*1000 -> 4697 | AH19: =IF(E41,E19/E41,0)*1000 -> 11858 | AI19: =IF(F41,F19/F41,0)*1000 -> 6166.7241 | AJ19: =IF(G41,G19/G41,0)*1000 -> 3480 | AK19: =IF(H41,H19/H41,0)*1000 -> 14025 | AL19: =IF(I41,I19/I41,0)*1000 -> 9219.2143 | AM19: =IF(J41,J19/J41,0)*1000 -> 0 | ... BF19: =IF(AC41,AC19/AC41,0)*1000 -> 8009.4065
B20: 2017 | C20: =HLOOKUP(C12,'2017 CHF'!$D$57:$AC$73,$A$14,FALSE) -> 0 | D20: =HLOOKUP(D12,'2017 CHF'!$D$57:$AC$73,$A$14,FALSE) -> 0 | E20: =HLOOKUP(E12,'2017 CHF'!$D$57:$AC$73,$A$14,FALSE) -> 0 | F20: =HLOOKUP(F12,'2017 CHF'!$D$57:$AC$73,$A$14,FALSE) -> 102.49 | G20: =HLOOKUP(G12,'2017 CHF'!$D$57:$AC$73,$A$14,FALSE) -> 0 | H20: =HLOOKUP(H12,'2017 CHF'!$D$57:$AC$73,$A$14,FALSE) -> 0 | I20: =HLOOKUP(I12,'2017 CHF'!$D$57:$AC$73,$A$14,FALSE) -> 53.255 | J20: =HLOOKUP(J12,'2017 CHF'!$D$57:$AC$73,$A$14,FALSE) -> 0 | ... AB20: =HLOOKUP(AB12,'2017 CHF'!$D$57:$AC$73,$A$14,FALSE) -> 0 | AC20: =SUM(C20:AB20) -> 459.23 | AE20: 2017 | AF20: =IF(C42,C20/C42,0)*1000 -> 0 | AG20: =IF(D42,D20/D42,0)*1000 -> 0 | AH20: =IF(E42,E20/E42,0)*1000 -> 0 | AI20: =IF(F42,F20/F42,0)*1000 -> 6832.6667 | AJ20: =IF(G42,G20/G42,0)*1000 -> 0 | AK20: =IF(H42,H20/H42,0)*1000 -> 0 | AL20: =IF(I42,I20/I42,0)*1000 -> 8875.8333 | AM20: =IF(J42,J20/J42,0)*1000 -> 0 | ... BF20: =IF(AC42,AC20/AC42,0)*1000 -> 8200.5357
AE21: Average | AF21: =SUM(C13:C20)/SUM(C35:C42)*1000 -> 7147.4895 | AG21: =SUM(D13:D20)/SUM(D35:D42)*1000 -> 6006.0714 | AH21: =SUM(E13:E20)/SUM(E35:E42)*1000 -> 7002.2083 | AI21: =SUM(F13:F20)/SUM(F35:F42)*1000 -> 8584.7893 | AJ21: =SUM(G13:G20)/SUM(G35:G42)*1000 -> 10606.04 | AK21: =SUM(H13:H20)/SUM(H35:H42)*1000 -> 20260.534 | AL21: =SUM(I13:I20)/SUM(I35:I42)*1000 -> 11539.151 | AM21: =SUM(J13:J20)/SUM(J35:J42)*1000 -> 14992.725 | ... BE21: =SUM(AB13:AB20)/SUM(AB35:AB42)*1000 -> 10758.155 | BF21: =SUM(C13:AB20)/SUM(C35:AB42)*1000 -> 11170.948
A23: Index | B23: HP - SFH - MoPEC 2015 - Buildings | C23: AG | D23: AI | E23: AR | F23: BE | G23: BL | H23: BS | I23: FR | J23: GE | K23: GL | L23: GR | M23: JU | N23: LU | O23: NE | P23: NW | Q23: OW | R23: SG | S23: SH | T23: SO | U23: SZ | V23: TG | W23: TI | X23: UR | Y23: VD | Z23: VS | AA23: ZG | AB23: ZH
B24: 2024 | C24: =HLOOKUP(C23,'2024'!$D$57:$AC$69,$A$25,FALSE) -> 1616 | D24: =HLOOKUP(D23,'2024'!$D$57:$AC$69,$A$25,FALSE) -> 36 | E24: =HLOOKUP(E23,'2024'!$D$57:$AC$69,$A$25,FALSE) -> 200 | F24: =HLOOKUP(F23,'2024'!$D$57:$AC$69,$A$25,FALSE) -> 2104 | G24: =HLOOKUP(G23,'2024'!$D$57:$AC$69,$A$25,FALSE) -> 974 | H24: =HLOOKUP(H23,'2024'!$D$57:$AC$69,$A$25,FALSE) -> 368 | I24: =HLOOKUP(I23,'2024'!$D$57:$AC$69,$A$25,FALSE) -> 833 | J24: =HLOOKUP(J23,'2024'!$D$57:$AC$69,$A$25,FALSE) -> 631 | ... AB24: =HLOOKUP(AB23,'2024'!$D$57:$AC$69,$A$25,FALSE) -> 2790 | AC24: =SUM(C24:AB24) -> 17753
A25: 11 | B25: 2023 | C25: =HLOOKUP(C23,'2023'!$D$57:$AC$69,$A$25,FALSE) -> 1798 | D25: =HLOOKUP(D23,'2023'!$D$57:$AC$69,$A$25,FALSE) -> 35 | E25: =HLOOKUP(E23,'2023'!$D$57:$AC$69,$A$25,FALSE) -> 268 | F25: =HLOOKUP(F23,'2023'!$D$57:$AC$69,$A$25,FALSE) -> 2571 | G25: =HLOOKUP(G23,'2023'!$D$57:$AC$69,$A$25,FALSE) -> 1241 | H25: =HLOOKUP(H23,'2023'!$D$57:$AC$69,$A$25,FALSE) -> 275 | I25: =HLOOKUP(I23,'2023'!$D$57:$AC$69,$A$25,FALSE) -> 1067 | J25: =HLOOKUP(J23,'2023'!$D$57:$AC$69,$A$25,FALSE) -> 458 | ... AB25: =HLOOKUP(AB23,'2023'!$D$57:$AC$69,$A$25,FALSE) -> 2458 | AC25: =SUM(C25:AB25) -> 19966
B26: 2022 | C26: =HLOOKUP(C23,'2022'!$D$57:$AC$69,$A$25,FALSE) -> 1102 | D26: =HLOOKUP(D23,'2022'!$D$57:$AC$69,$A$25,FALSE) -> 31 | E26: =HLOOKUP(E23,'2022'!$D$57:$AC$69,$A$25,FALSE) -> 87 | F26: =HLOOKUP(F23,'2022'!$D$57:$AC$69,$A$25,FALSE) -> 2004 | G26: =HLOOKUP(G23,'2022'!$D$57:$AC$69,$A$25,FALSE) -> 838 | H26: =HLOOKUP(H23,'2022'!$D$57:$AC$69,$A$25,FALSE) -> 120 | I26: =HLOOKUP(I23,'2022'!$D$57:$AC$69,$A$25,FALSE) -> 865 | J26: =HLOOKUP(J23,'2022'!$D$57:$AC$69,$A$25,FALSE) -> 239 | ... AB26: =HLOOKUP(AB23,'2022'!$D$57:$AC$69,$A$25,FALSE) -> 1932 | AC26: =SUM(C26:AB26) -> 12773
B27: 2021 | C27: =HLOOKUP(C23,'2021'!$D$57:$AC$69,$A$25,FALSE) -> 226 | D27: =HLOOKUP(D23,'2021'!$D$57:$AC$69,$A$25,FALSE) -> 7 | E27: =HLOOKUP(E23,'2021'!$D$57:$AC$69,$A$25,FALSE) -> 42 | F27: =HLOOKUP(F23,'2021'!$D$57:$AC$69,$A$25,FALSE) -> 1911 | G27: =HLOOKUP(G23,'2021'!$D$57:$AC$69,$A$25,FALSE) -> 599 | H27: =HLOOKUP(H23,'2021'!$D$57:$AC$69,$A$25,FALSE) -> 123 | I27: =HLOOKUP(I23,'2021'!$D$57:$AC$69,$A$25,FALSE) -> 483 | J27: =HLOOKUP(J23,'2021'!$D$57:$AC$69,$A$25,FALSE) -> 191 | ... AB27: =HLOOKUP(AB23,'2021'!$D$57:$AC$69,$A$25,FALSE) -> 1173 | AC27: =SUM(C27:AB27) -> 9166
B28: 2020 | C28: =HLOOKUP(C23,'2020'!$D$57:$AC$69,$A$25,FALSE) -> 0 | D28: =HLOOKUP(D23,'2020'!$D$57:$AC$69,$A$25,FALSE) -> 22 | E28: =HLOOKUP(E23,'2020'!$D$57:$AC$69,$A$25,FALSE) -> 28 | F28: =HLOOKUP(F23,'2020'!$D$57:$AC$69,$A$25,FALSE) -> 1059 | G28: =HLOOKUP(G23,'2020'!$D$57:$AC$69,$A$25,FALSE) -> 120 | H28: =HLOOKUP(H23,'2020'!$D$57:$AC$69,$A$25,FALSE) -> 80 | I28: =HLOOKUP(I23,'2020'!$D$57:$AC$69,$A$25,FALSE) -> 344 | J28: =HLOOKUP(J23,'2020'!$D$57:$AC$69,$A$25,FALSE) -> 122 | ... AB28: =HLOOKUP(AB23,'2020'!$D$57:$AC$69,$A$25,FALSE) -> 87 | AC28: =SUM(C28:AB28) -> 4786
B29: 2019 | C29: =HLOOKUP(C23,'2019'!$D$57:$AC$69,$A$25,FALSE) -> 0 | D29: =HLOOKUP(D23,'2019'!$D$57:$AC$69,$A$25,FALSE) -> 17 | E29: =HLOOKUP(E23,'2019'!$D$57:$AC$69,$A$25,FALSE) -> 15 | F29: =HLOOKUP(F23,'2019'!$D$57:$AC$69,$A$25,FALSE) -> 444 | G29: =HLOOKUP(G23,'2019'!$D$57:$AC$69,$A$25,FALSE) -> 37 | H29: =HLOOKUP(H23,'2019'!$D$57:$AC$69,$A$25,FALSE) -> 27 | I29: =HLOOKUP(I23,'2019'!$D$57:$AC$69,$A$25,FALSE) -> 225 | J29: =HLOOKUP(J23,'2019'!$D$57:$AC$69,$A$25,FALSE) -> 123 | ... AB29: =HLOOKUP(AB23,'2019'!$D$57:$AC$69,$A$25,FALSE) -> 0 | AC29: =SUM(C29:AB29) -> 2577
B30: 2018 | C30: =HLOOKUP(C23,'2018'!$D$57:$AC$69,$A$25,FALSE) -> 0 | D30: =HLOOKUP(D23,'2018'!$D$57:$AC$69,$A$25,FALSE) -> 7 | E30: =HLOOKUP(E23,'2018'!$D$57:$AC$69,$A$25,FALSE) -> 15 | F30: =HLOOKUP(F23,'2018'!$D$57:$AC$69,$A$25,FALSE) -> 332 | G30: =HLOOKUP(G23,'2018'!$D$57:$AC$69,$A$25,FALSE) -> 42 | H30: =HLOOKUP(H23,'2018'!$D$57:$AC$69,$A$25,FALSE) -> 9 | I30: =HLOOKUP(I23,'2018'!$D$57:$AC$69,$A$25,FALSE) -> 184 | J30: =HLOOKUP(J23,'2018'!$D$57:$AC$69,$A$25,FALSE) -> 77 | ... AB30: =HLOOKUP(AB23,'2018'!$D$57:$AC$69,$A$25,FALSE) -> 0 | AC30: =SUM(C30:AB30) -> 1684
B31: 2017 | C31: =HLOOKUP(C23,'2017'!$D$57:$AC$69,$A$25,FALSE) -> 0 | D31: =HLOOKUP(D23,'2017'!$D$57:$AC$69,$A$25,FALSE) -> 0 | E31: =HLOOKUP(E23,'2017'!$D$57:$AC$69,$A$25,FALSE) -> 0 | F31: =HLOOKUP(F23,'2017'!$D$57:$AC$69,$A$25,FALSE) -> 83 | G31: =HLOOKUP(G23,'2017'!$D$57:$AC$69,$A$25,FALSE) -> 7 | H31: =HLOOKUP(H23,'2017'!$D$57:$AC$69,$A$25,FALSE) -> 0 | I31: =HLOOKUP(I23,'2017'!$D$57:$AC$69,$A$25,FALSE) -> 19 | J31: =HLOOKUP(J23,'2017'!$D$57:$AC$69,$A$25,FALSE) -> 74 | ... AB31: =HLOOKUP(AB23,'2017'!$D$57:$AC$69,$A$25,FALSE) -> 0 | AC31: =SUM(C31:AB31) -> 351
A34: Index | B34: HP - MFH - MoPEC 2015 - Buildings | C34: AG | D34: AI | E34: AR | F34: BE | G34: BL | H34: BS | I34: FR | J34: GE | K34: GL | L34: GR | M34: JU | N34: LU | O34: NE | P34: NW | Q34: OW | R34: SG | S34: SH | T34: SO | U34: SZ | V34: TG | W34: TI | X34: UR | Y34: VD | Z34: VS | AA34: ZG | AB34: ZH
B35: 2024 | C35: =HLOOKUP(C34,'2024'!$D$57:$AC$69,$A$36,FALSE) -> 268 | D35: =HLOOKUP(D34,'2024'!$D$57:$AC$69,$A$36,FALSE) -> 2 | E35: =HLOOKUP(E34,'2024'!$D$57:$AC$69,$A$36,FALSE) -> 32 | F35: =HLOOKUP(F34,'2024'!$D$57:$AC$69,$A$36,FALSE) -> 470 | G35: =HLOOKUP(G34,'2024'!$D$57:$AC$69,$A$36,FALSE) -> 126 | H35: =HLOOKUP(H34,'2024'!$D$57:$AC$69,$A$36,FALSE) -> 52 | I35: =HLOOKUP(I34,'2024'!$D$57:$AC$69,$A$36,FALSE) -> 101 | J35: =HLOOKUP(J34,'2024'!$D$57:$AC$69,$A$36,FALSE) -> 25 | ... AB35: =HLOOKUP(AB34,'2024'!$D$57:$AC$69,$A$36,FALSE) -> 814 | AC35: =SUM(C35:AB35) -> 3479
A36: 12 | B36: 2023 | C36: =HLOOKUP(C34,'2023'!$D$57:$AC$69,$A$36,FALSE) -> 203 | D36: =HLOOKUP(D34,'2023'!$D$57:$AC$69,$A$36,FALSE) -> 7 | E36: =HLOOKUP(E34,'2023'!$D$57:$AC$69,$A$36,FALSE) -> 16 | F36: =HLOOKUP(F34,'2023'!$D$57:$AC$69,$A$36,FALSE) -> 450 | G36: =HLOOKUP(G34,'2023'!$D$57:$AC$69,$A$36,FALSE) -> 115 | H36: =HLOOKUP(H34,'2023'!$D$57:$AC$69,$A$36,FALSE) -> 32 | I36: =HLOOKUP(I34,'2023'!$D$57:$AC$69,$A$36,FALSE) -> 110 | J36: =HLOOKUP(J34,'2023'!$D$57:$AC$69,$A$36,FALSE) -> 8 | ... AB36: =HLOOKUP(AB34,'2023'!$D$57:$AC$69,$A$36,FALSE) -> 549 | AC36: =SUM(C36:AB36) -> 2825
B37: 2022 | C37: =HLOOKUP(C34,'2022'!$D$57:$AC$69,$A$36,FALSE) -> 108 | D37: =HLOOKUP(D34,'2022'!$D$57:$AC$69,$A$36,FALSE) -> 4 | E37: =HLOOKUP(E34,'2022'!$D$57:$AC$69,$A$36,FALSE) -> 6 | F37: =HLOOKUP(F34,'2022'!$D$57:$AC$69,$A$36,FALSE) -> 273 | G37: =HLOOKUP(G34,'2022'!$D$57:$AC$69,$A$36,FALSE) -> 72 | H37: =HLOOKUP(H34,'2022'!$D$57:$AC$69,$A$36,FALSE) -> 21 | I37: =HLOOKUP(I34,'2022'!$D$57:$AC$69,$A$36,FALSE) -> 80 | J37: =HLOOKUP(J34,'2022'!$D$57:$AC$69,$A$36,FALSE) -> 3 | ... AB37: =HLOOKUP(AB34,'2022'!$D$57:$AC$69,$A$36,FALSE) -> 383 | AC37: =SUM(C37:AB37) -> 1763
B38: 2021 | C38: =HLOOKUP(C34,'2021'!$D$57:$AC$69,$A$36,FALSE) -> 38 | D38: =HLOOKUP(D34,'2021'!$D$57:$AC$69,$A$36,FALSE) -> 4 | E38: =HLOOKUP(E34,'2021'!$D$57:$AC$69,$A$36,FALSE) -> 8 | F38: =HLOOKUP(F34,'2021'!$D$57:$AC$69,$A$36,FALSE) -> 284 | G38: =HLOOKUP(G34,'2021'!$D$57:$AC$69,$A$36,FALSE) -> 48 | H38: =HLOOKUP(H34,'2021'!$D$57:$AC$69,$A$36,FALSE) -> 27 | I38: =HLOOKUP(I34,'2021'!$D$57:$AC$69,$A$36,FALSE) -> 60 | J38: =HLOOKUP(J34,'2021'!$D$57:$AC$69,$A$36,FALSE) -> 2 | ... AB38: =HLOOKUP(AB34,'2021'!$D$57:$AC$69,$A$36,FALSE) -> 215 | AC38: =SUM(C38:AB38) -> 1314
B39: 2020 | C39: =HLOOKUP(C34,'2020'!$D$57:$AC$69,$A$36,FALSE) -> 0 | D39: =HLOOKUP(D34,'2020'!$D$57:$AC$69,$A$36,FALSE) -> 3 | E39: =HLOOKUP(E34,'2020'!$D$57:$AC$69,$A$36,FALSE) -> 3 | F39: =HLOOKUP(F34,'2020'!$D$57:$AC$69,$A$36,FALSE) -> 160 | G39: =HLOOKUP(G34,'2020'!$D$57:$AC$69,$A$36,FALSE) -> 11 | H39: =HLOOKUP(H34,'2020'!$D$57:$AC$69,$A$36,FALSE) -> 11 | I39: =HLOOKUP(I34,'2020'!$D$57:$AC$69,$A$36,FALSE) -> 40 | J39: =HLOOKUP(J34,'2020'!$D$57:$AC$69,$A$36,FALSE) -> 1 | ... AB39: =HLOOKUP(AB34,'2020'!$D$57:$AC$69,$A$36,FALSE) -> 41 | AC39: =SUM(C39:AB39) -> 718
B40: 2019 | C40: =HLOOKUP(C34,'2019'!$D$57:$AC$69,$A$36,FALSE) -> 0 | D40: =HLOOKUP(D34,'2019'!$D$57:$AC$69,$A$36,FALSE) -> 4 | E40: =HLOOKUP(E34,'2019'!$D$57:$AC$69,$A$36,FALSE) -> 4 | F40: =HLOOKUP(F34,'2019'!$D$57:$AC$69,$A$36,FALSE) -> 65 | G40: =HLOOKUP(G34,'2019'!$D$57:$AC$69,$A$36,FALSE) -> 1 | H40: =HLOOKUP(H34,'2019'!$D$57:$AC$69,$A$36,FALSE) -> 4 | I40: =HLOOKUP(I34,'2019'!$D$57:$AC$69,$A$36,FALSE) -> 23 | J40: =HLOOKUP(J34,'2019'!$D$57:$AC$69,$A$36,FALSE) -> 1 | ... AB40: =HLOOKUP(AB34,'2019'!$D$57:$AC$69,$A$36,FALSE) -> 0 | AC40: =SUM(C40:AB40) -> 345
B41: 2018 | C41: =HLOOKUP(C34,'2018'!$D$57:$AC$69,$A$36,FALSE) -> 0 | D41: =HLOOKUP(D34,'2018'!$D$57:$AC$69,$A$36,FALSE) -> 4 | E41: =HLOOKUP(E34,'2018'!$D$57:$AC$69,$A$36,FALSE) -> 3 | F41: =HLOOKUP(F34,'2018'!$D$57:$AC$69,$A$36,FALSE) -> 58 | G41: =HLOOKUP(G34,'2018'!$D$57:$AC$69,$A$36,FALSE) -> 1 | H41: =HLOOKUP(H34,'2018'!$D$57:$AC$69,$A$36,FALSE) -> 1 | I41: =HLOOKUP(I34,'2018'!$D$57:$AC$69,$A$36,FALSE) -> 7 | J41: =HLOOKUP(J34,'2018'!$D$57:$AC$69,$A$36,FALSE) -> 0 | ... AB41: =HLOOKUP(AB34,'2018'!$D$57:$AC$69,$A$36,FALSE) -> 0 | AC41: =SUM(C41:AB41) -> 201
B42: 2017 | C42: =HLOOKUP(C34,'2017'!$D$57:$AC$69,$A$36,FALSE) -> 0 | D42: =HLOOKUP(D34,'2017'!$D$57:$AC$69,$A$36,FALSE) -> 0 | E42: =HLOOKUP(E34,'2017'!$D$57:$AC$69,$A$36,FALSE) -> 0 | F42: =HLOOKUP(F34,'2017'!$D$57:$AC$69,$A$36,FALSE) -> 15 | G42: =HLOOKUP(G34,'2017'!$D$57:$AC$69,$A$36,FALSE) -> 0 | H42: =HLOOKUP(H34,'2017'!$D$57:$AC$69,$A$36,FALSE) -> 0 | I42: =HLOOKUP(I34,'2017'!$D$57:$AC$69,$A$36,FALSE) -> 6 | J42: =HLOOKUP(J34,'2017'!$D$57:$AC$69,$A$36,FALSE) -> 0 | ... AB42: =HLOOKUP(AB34,'2017'!$D$57:$AC$69,$A$36,FALSE) -> 0 | AC42: =SUM(C42:AB42) -> 56
AC51: =SUM(C51:AB51) -> 0
AC52: =SUM(C52:AB52) -> 0 | AE52: 226620.56 | AG52: =AE52/AC25 -> 11.350323
...

Sheet 2024
A1: SFH
A2: Measure | B2: Unit | C2: CH | D2: ZH | E2: BE | F2: LU | G2: UR | H2: SZ | I2: OW | J2: NW | K2: GL | L2: ZG | M2: FR | N2: SO | O2: BS | P2: BL | Q2: SH | R2: AR | S2: AI | T2: SG | U2: GR | V2: AG | W2: TG | X2: TI | Y2: VD | Z2: VS | AA2: NE | AB2: GE | AC2: JU
A3: Wood/pellet with daily tank | B3: - | C3: 138 | D3: 0 | E3: 0 | F3: 4 | G3: 1 | H3: 5 | I3: 2 | J3: 0 | K3: 7 | L3: 0 | M3: 9 | N3: 6 | O3: 0 | P3: 9 | Q3: 4 | R3: 5 | S3: 0 | T3: 4 | U3: 24 | V3: 14 | W3: 10 | X3: 14 | Y3: 11 | Z3: 5 | AA3: 0 | AB3: 0 | AC3: 4
A4: Automatic wood heating, heat output ≤ 70 kW | B4: - | C4: 406 | D4: 0 | E4: 126 | F4: 8 | G4: 1 | H4: 0 | I4: 0 | J4: 0 | K4: 4 | L4: 0 | M4: 15 | N4: 20 | O4: 6 | P4: 11 | Q4: 8 | R4: 1 | S4: 1 | T4: 0 | U4: 28 | V4: 15 | W4: 15 | X4: 9 | Y4: 70 | Z4: 15 | AA4: 42 | AB4: 0 | AC4: 11
A5: Automatic wood heating, heat output > 70 kW | B5: - | C5: 2 | D5: 0 | E5: 0 | F5: 0 | G5: 0 | H5: 0 | I5: 0 | J5: 0 | K5: 0 | L5: 0 | M5: 0 | N5: 0 | O5: 0 | P5: 1 | Q5: 0 | R5: 0 | S5: 0 | T5: 0 | U5: 0 | V5: 0 | W5: 0 | X5: 0 | Y5: 1 | Z5: 0 | AA5: 0 | AB5: 0 | AC5: 0
A6: HP air-water | B6: - | C6: 13708 | D6: 1651 | E6: 1780 | F6: 403 | G6: 14 | H6: 168 | I6: 8 | J6: 23 | K6: 135 | L6: 64 | M6: 629 | N6: 698 | O6: 176 | P6: 898 | Q6: 107 | R6: 173 | S6: 23 | T6: 719 | U6: 257 | V6: 1340 | W6: 510 | X6: 946 | Y6: 1119 | Z6: 717 | AA6: 387 | AB6: 621 | AC6: 142
A7: HP electric (brine/water, water/water) | B7: - | C7: 4045 | D7: 1139 | E7: 324 | F7: 344 | G7: 1 | H7: 42 | I7: 5 | J7: 1 | K7: 3 | L7: 90 | M7: 204 | N7: 127 | O7: 192 | P7: 76 | Q7: 28 | R7: 27 | S7: 13 | T7: 314 | U7: 99 | V7: 276 | W7: 307 | X7: 25 | Y7: 357 | Z7: 26 | AA7: 10 | AB7: 10 | AC7: 5
A8: DH | B8: - | C8: 1138 | D8: 169 | E8: 281 | F8: 48 | G8: 3 | H8: 91 | I8: 5 | J8: 4 | K8: 8 | L8: 3 | M8: 54 | N8: 22 | O8: 59 | P8: 11 | Q8: 66 | R8: 15 | S8: 2 | T8: 5 | U8: 26 | V8: 34 | W8: 68 | X8: 48 | Y8: 22 | Z8: 39 | AA8: 54 | AB8: 1 | AC8: 0
A9: ST | B9: - | C9: 320 | D9: 15 | E9: 34 | F9: 15 | G9: 1 | H9: 3 | I9: 0 | J9: 1 | K9: 7 | L9: 0 | M9: 9 | N9: 8 | O9: 2 | P9: 6 | Q9: 1 | R9: 3 | S9: 1 | T9: 0 | U9: 15 | V9: 13 | W9: 15 | X9: 13 | Y9: 113 | Z9: 10 | AA9: 10 | AB9: 13 | AC9: 12
A10: Ventilation and heat recovery | B10: - | C10: 11 | D10: 0 | E10: 1 | F10: 0 | G10: 0 | H10: 0 | I10: 0 | J10: 0 | K10: 0 | L10: 0 | M10: 0 | N10: 0 | O10: 2 | P10: 0 | Q10: 2 | R10: 0 | S10: 0 | T10: 0 | U10: 1 | V10: 0 | W10: 1 | X10: 0 | Y10: 4 | Z10: 0 | AA10: 0 | AB10: 0 | AC10: 0
A12: MFH
A13: Measure | B13: Unit | C13: CH | D13: ZH | E13: BE | F13: LU | G13: UR | H13: SZ | I13: OW | J13: NW | K13: GL | L13: ZG | M13: FR | N13: SO | O13: BS | P13: BL | Q13: SH | R13: AR | S13: AI | T13: SG | U13: GR | V13: AG | W13: TG | X13: TI | Y13: VD | Z13: VS | AA13: NE | AB13: GE | AC13: JU
A14: Wood/pellet with daily tank | B14: - | C14: 30 | D14: 0 | E14: 0 | F14: 3 | G14: 1 | H14: 4 | I14: 4 | J14: 0 | K14: 0 | L14: 0 | M14: 0 | N14: 2 | O14: 0 | P14: 1 | Q14: 1 | R14: 1 | S14: 0 | T14: 0 | U14: 6 | V14: 3 | W14: 3 | X14: 0 | Y14: 0 | Z14: 0 | AA14: 0 | AB14: 0 | AC14: 1
A15: Automatic wood heating, heat output ≤ 70 kW | B15: - | C15: 195 | D15: 0 | E15: 33 | F15: 8 | G15: 2 | H15: 2 | I15: 0 | J15: 3 | K15: 2 | L15: 0 | M15: 6 | N15: 9 | O15: 6 | P15: 5 | Q15: 3 | R15: 1 | S15: 1 | T15: 0 | U15: 32 | V15: 4 | W15: 12 | X15: 4 | Y15: 31 | Z15: 3 | AA15: 23 | AB15: 0 | AC15: 5
A16: Automatic wood heating, heat output > 70 kW | B16: - | C16: 32 | D16: 0 | E16: 8 | F16: 1 | G16: 0 | H16: 1 | I16: 0 | J16: 0 | K16: 0 | L16: 2 | M16: 0 | N16: 0 | O16: 0 | P16: 3 | Q16: 1 | R16: 0 | S16: 0 | T16: 0 | U16: 6 | V16: 0 | W16: 2 | X16: 2 | Y16: 2 | Z16: 3 | AA16: 1 | AB16: 0 | AC16: 0
A17: HP air-water | B17: - | C17: 1895 | D17: 305 | E17: 346 | F17: 108 | G17: 7 | H17: 71 | I17: 1 | J17: 29 | K17: 12 | L17: 32 | M17: 58 | N17: 98 | O17: 30 | P17: 96 | Q17: 17 | R17: 26 | S17: 1 | T17: 26 | U17: 102 | V17: 159 | W17: 58 | X17: 70 | Y17: 90 | Z17: 64 | AA17: 46 | AB17: 25 | AC17: 18
A18: HP electric (brine/water, water/water) | B18: - | C18: 1584 | D18: 509 | E18: 124 | F18: 230 | G18: 5 | H18: 27 | I18: 3 | J18: 15 | K18: 6 | L18: 109 | M18: 43 | N18: 34 | O18: 22 | P18: 30 | Q18: 10 | R18: 6 | S18: 1 | T18: 59 | U18: 97 | V18: 109 | W18: 68 | X18: 13 | Y18: 48 | Z18: 13 | AA18: 2 | AB18: 0 | AC18: 1
A19: DH | B19: - | C19: 1734 | D19: 333 | E19: 321 | F19: 89 | G19: 15 | H19: 94 | I19: 13 | J19: 16 | K19: 12 | L19: 37 | M19: 83 | N19: 37 | O19: 140 | P19: 35 | Q19: 57 | R19: 13 | S19: 1 | T19: 1 | U19: 60 | V19: 115 | W19: 44 | X19: 20 | Y19: 76 | Z19: 67 | AA19: 55 | AB19: 0 | AC19: 0
A20: ST | B20: - | C20: 148 | D20: 4 | E20: 25 | F20: 9 | G20: 0 | H20: 6 | I20: 0 | J20: 0 | K20: 1 | L20: 0 | M20: 3 | N20: 1 | O20: 1 | P20: 0 | Q20: 1 | R20: 2 | S20: 0 | T20: 1 | U20: 14 | V20: 6 | W20: 1 | X20: 6 | Y20: 40 | Z20: 1 | AA20: 7 | AB20: 16 | AC20: 3
A21: Ventilation and heat recovery | B21: - | C21: 12 | D21: 0 | E21: 1 | F21: 0 | G21: 0 | H21: 0 | I21: 0 | J21: 0 | K21: 0 | L21: 0 | M21: 0 | N21: 0 | O21: 1 | P21: 0 | Q21: 0 | R21: 0 | S21: 0 | T21: 0 | U21: 5 | V21: 0 | W21: 0 | X21: 0 | Y21: 2 | Z21: 0 | AA21: 0 | AB21: 3 | AC21: 0
A23: Non Res
A24: Measure | B24: Unit | C24: CH | D24: ZH | E24: BE | F24: LU | G24: UR | H24: SZ | I24: OW | J24: NW | K24: GL | L24: ZG | M24: FR | N24: SO | O24: BS | P24: BL | Q24: SH | R24: AR | S24: AI | T24: SG | U24: GR | V24: AG | W24: TG | X24: TI | Y24: VD | Z24: VS | AA24: NE | AB24: GE | AC24: JU
A25: Wood/pellet with daily tank | B25: - | C25: 4 | D25: 0 | E25: 0 | F25: 0 | G25: 0 | H25: 0 | I25: 0 | J25: 0 | K25: 1 | L25: 0 | M25: 0 | N25: 0 | O25: 0 | P25: 0 | Q25: 0 | R25: 0 | S25: 0 | T25: 0 | U25: 1 | V25: 0 | W25: 1 | X25: 1 | Y25: 0 | Z25: 0 | AA25: 0 | AB25: 0 | AC25: 0
A26: Automatic wood heating, heat output ≤ 70 kW | B26: - | C26: 33 | D26: 0 | E26: 8 | F26: 1 | G26: 0 | H26: 0 | I26: 0 | J26: 1 | K26: 1 | L26: 0 | M26: 2 | N26: 4 | O26: 0 | P26: 2 | Q26: 0 | R26: 2 | S26: 0 | T26: 0 | U26: 3 | V26: 1 | W26: 3 | X26: 0 | Y26: 2 | Z26: 2 | AA26: 1 | AB26: 0 | AC26: 0
A27: Automatic wood heating, heat output > 70 kW | B27: - | C27: 13 | D27: 0 | E27: 2 | F27: 2 | G27: 0 | H27: 0 | I27: 0 | J27: 0 | K27: 0 | L27: 0 | M27: 1 | N27: 0 | O27: 0 | P27: 1 | Q27: 0 | R27: 0 | S27: 0 | T27: 1 | U27: 1 | V27: 0 | W27: 2 | X27: 0 | Y27: 1 | Z27: 2 | AA27: 0 | AB27: 0 | AC27: 0
A28: HP air-water | B28: - | C28: 241 | D28: 34 | E28: 30 | F28: 10 | G28: 2 | H28: 5 | I28: 0 | J28: 1 | K28: 2 | L28: 4 | M28: 4 | N28: 14 | O28: 1 | P28: 14 | Q28: 8 | R28: 1 | S28: 1 | T28: 4 | U28: 7 | V28: 26 | W28: 22 | X28: 15 | Y28: 9 | Z28: 10 | AA28: 4 | AB28: 3 | AC28: 10
A29: HP electric (brine/water, water/water) | B29: - | C29: 123 | D29: 18 | E29: 8 | F29: 12 | G29: 0 | H29: 5 | I29: 0 | J29: 1 | K29: 1 | L29: 0 | M29: 1 | N29: 7 | O29: 1 | P29: 1 | Q29: 2 | R29: 1 | S29: 1 | T29: 10 | U29: 4 | V29: 9 | W29: 23 | X29: 6 | Y29: 7 | Z29: 3 | AA29: 0 | AB29: 2 | AC29: 0
A30: DH | B30: - | C30: 312 | D30: 37 | E30: 47 | F30: 19 | G30: 2 | H30: 24 | I30: 0 | J30: 4 | K30: 8 | L30: 15 | M30: 16 | N30: 10 | O30: 12 | P30: 8 | Q30: 20 | R30: 0 | S30: 0 | T30: 0 | U30: 9 | V30: 25 | W30: 14 | X30: 8 | Y30: 16 | Z30: 16 | AA30: 1 | AB30: 1 | AC30: 0
A31: ST | B31: - | C31: 10 | D31: 0 | E31: 2 | F31: 1 | G31: 0 | H31: 0 | I31: 0 | J31: 0 | K31: 0 | L31: 0 | M31: 1 | N31: 0 | O31: 0 | P31: 0 | Q31: 0 | R31: 0 | S31: 0 | T31: 0 | U31: 1 | V31: 0 | W31: 0 | X31: 2 | Y31: 1 | Z31: 1 | AA31: 0 | AB31: 1 | AC31: 0
A32: Ventilation and heat recovery | B32: - | C32: 0 | D32: 0 | E32: 0 | F32: 0 | G32: 0 | H32: 0 | I32: 0 | J32: 0 | K32: 0 | L32: 0 | M32: 0 | N32: 0 | O32: 0 | P32: 0 | Q32: 0 | R32: 0 | S32: 0 | T32: 0 | U32: 0 | V32: 0 | W32: 0 | X32: 0 | Y32: 0 | Z32: 0 | AA32: 0 | AB32: 0 | AC32: 0
A34: SFH
A35: Measure | B35: Index | D35: AG | E35: AI | F35: AR | G35: BE | H35: BL | I35: BS | J35: FR | K35: GE | L35: GL | M35: GR | N35: JU | O35: LU | P35: NE | Q35: NW | R35: OW | S35: SG | T35: SH | U35: SO | V35: SZ | W35: TG | X35: TI | Y35: UR | Z35: VD | AA35: VS | AB35: ZG | AC35: ZH
A36: Wood/pellet with daily tank | B36: 2 | D36: =HLOOKUP(D$35,$D$2:$AC$10,$B36,FALSE) -> 14 | E36: =HLOOKUP(E$35,$D$2:$AC$10,$B36,FALSE) -> 0 | F36: =HLOOKUP(F$35,$D$2:$AC$10,$B36,FALSE) -> 5 | G36: =HLOOKUP(G$35,$D$2:$AC$10,$B36,FALSE) -> 0 | H36: =HLOOKUP(H$35,$D$2:$AC$10,$B36,FALSE) -> 9 | I36: =HLOOKUP(I$35,$D$2:$AC$10,$B36,FALSE) -> 0 | J36: =HLOOKUP(J$35,$D$2:$AC$10,$B36,FALSE) -> 9 | K36: =HLOOKUP(K$35,$D$2:$AC$10,$B36,FALSE) -> 0 | ... AC36: =HLOOKUP(AC$35,$D$2:$AC$10,$B36,FALSE) -> 0
A37: Automatic wood heating, heat output ≤ 70 kW | B37: 3 | D37: =HLOOKUP(D$35,$D$2:$AC$10,$B37,FALSE) -> 15 | E37: =HLOOKUP(E$35,$D$2:$AC$10,$B37,FALSE) -> 1 | F37: =HLOOKUP(F$35,$D$2:$AC$10,$B37,FALSE) -> 1 | G37: =HLOOKUP(G$35,$D$2:$AC$10,$B37,FALSE) -> 126 | H37: =HLOOKUP(H$35,$D$2:$AC$10,$B37,FALSE) -> 11 | I37: =HLOOKUP(I$35,$D$2:$AC$10,$B37,FALSE) -> 6 | J37: =HLOOKUP(J$35,$D$2:$AC$10,$B37,FALSE) -> 15 | K37: =HLOOKUP(K$35,$D$2:$AC$10,$B37,FALSE) -> 0 | ... AC37: =HLOOKUP(AC$35,$D$2:$AC$10,$B37,FALSE) -> 0
A38: Automatic wood heating, heat output > 70 kW | B38: 4 | D38: =HLOOKUP(D$35,$D$2:$AC$10,$B38,FALSE) -> 0 | E38: =HLOOKUP(E$35,$D$2:$AC$10,$B38,FALSE) -> 0 | F38: =HLOOKUP(F$35,$D$2:$AC$10,$B38,FALSE) -> 0 | G38: =HLOOKUP(G$35,$D$2:$AC$10,$B38,FALSE) -> 0 | H38: =HLOOKUP(H$35,$D$2:$AC$10,$B38,FALSE) -> 1 | I38: =HLOOKUP(I$35,$D$2:$AC$10,$B38,FALSE) -> 0 | J38: =HLOOKUP(J$35,$D$2:$AC$10,$B38,FALSE) -> 0 | K38: =HLOOKUP(K$35,$D$2:$AC$10,$B38,FALSE) -> 0 | ... AC38: =HLOOKUP(AC$35,$D$2:$AC$10,$B38,FALSE) -> 0
A39: HP air-water | B39: 5 | D39: =HLOOKUP(D$35,$D$2:$AC$10,$B39,FALSE) -> 1340 | E39: =HLOOKUP(E$35,$D$2:$AC$10,$B39,FALSE) -> 23 | F39: =HLOOKUP(F$35,$D$2:$AC$10,$B39,FALSE) -> 173 | G39: =HLOOKUP(G$35,$D$2:$AC$10,$B39,FALSE) -> 1780 | H39: =HLOOKUP(H$35,$D$2:$AC$10,$B39,FALSE) -> 898 | I39: =HLOOKUP(I$35,$D$2:$AC$10,$B39,FALSE) -> 176 | J39: =HLOOKUP(J$35,$D$2:$AC$10,$B39,FALSE) -> 629 | K39: =HLOOKUP(K$35,$D$2:$AC$10,$B39,FALSE) -> 621 | ... AC39: =HLOOKUP(AC$35,$D$2:$AC$10,$B39,FALSE) -> 1651
A40: HP electric (brine/water, water/water) | B40: 6 | D40: =HLOOKUP(D$35,$D$2:$AC$10,$B40,FALSE) -> 276 | E40: =HLOOKUP(E$35,$D$2:$AC$10,$B40,FALSE) -> 13 | F40: =HLOOKUP(F$35,$D$2:$AC$10,$B40,FALSE) -> 27 | G40: =HLOOKUP(G$35,$D$2:$AC$10,$B40,FALSE) -> 324 | H40: =HLOOKUP(H$35,$D$2:$AC$10,$B40,FALSE) -> 76 | I40: =HLOOKUP(I$35,$D$2:$AC$10,$B40,FALSE) -> 192 | J40: =HLOOKUP(J$35,$D$2:$AC$10,$B40,FALSE) -> 204 | K40: =HLOOKUP(K$35,$D$2:$AC$10,$B40,FALSE) -> 10 | ... AC40: =HLOOKUP(AC$35,$D$2:$AC$10,$B40,FALSE) -> 1139
A41: DH | B41: 7 | D41: =HLOOKUP(D$35,$D$2:$AC$10,$B41,FALSE) -> 34 | E41: =HLOOKUP(E$35,$D$2:$AC$10,$B41,FALSE) -> 2 | F41: =HLOOKUP(F$35,$D$2:$AC$10,$B41,FALSE) -> 15 | G41: =HLOOKUP(G$35,$D$2:$AC$10,$B41,FALSE) -> 281 | H41: =HLOOKUP(H$35,$D$2:$AC$10,$B41,FALSE) -> 11 | I41: =HLOOKUP(I$35,$D$2:$AC$10,$B41,FALSE) -> 59 | J41: =HLOOKUP(J$35,$D$2:$AC$10,$B41,FALSE) -> 54 | K41: =HLOOKUP(K$35,$D$2:$AC$10,$B41,FALSE) -> 1 | ... AC41: =HLOOKUP(AC$35,$D$2:$AC$10,$B41,FALSE) -> 169
A42: ST | B42: 8 | D42: =HLOOKUP(D$35,$D$2:$AC$10,$B42,FALSE) -> 13 | E42: =HLOOKUP(E$35,$D$2:$AC$10,$B42,FALSE) -> 1 | F42: =HLOOKUP(F$35,$D$2:$AC$10,$B42,FALSE) -> 3 | G42: =HLOOKUP(G$35,$D$2:$AC$10,$B42,FALSE) -> 34 | H42: =HLOOKUP(H$35,$D$2:$AC$10,$B42,FALSE) -> 6 | I42: =HLOOKUP(I$35,$D$2:$AC$10,$B42,FALSE) -> 2 | J42: =HLOOKUP(J$35,$D$2:$AC$10,$B42,FALSE) -> 9 | K42: =HLOOKUP(K$35,$D$2:$AC$10,$B42,FALSE) -> 13 | ... AC42: =HLOOKUP(AC$35,$D$2:$AC$10,$B42,FALSE) -> 15
A43: Ventilation and heat recovery | B43: 9 | D43: =HLOOKUP(D$35,$D$2:$AC$10,$B43,FALSE) -> 0 | E43: =HLOOKUP(E$35,$D$2:$AC$10,$B43,FALSE) -> 0 | F43: =HLOOKUP(F$35,$D$2:$AC$10,$B43,FALSE) -> 0 | G43: =HLOOKUP(G$35,$D$2:$AC$10,$B43,FALSE) -> 1 | H43: =HLOOKUP(H$35,$D$2:$AC$10,$B43,FALSE) -> 0 | I43: =HLOOKUP(I$35,$D$2:$AC$10,$B43,FALSE) -> 2 | J43: =HLOOKUP(J$35,$D$2:$AC$10,$B43,FALSE) -> 0 | K43: =HLOOKUP(K$35,$D$2:$AC$10,$B43,FALSE) -> 0 | ... AC43: =HLOOKUP(AC$35,$D$2:$AC$10,$B43,FALSE) -> 0
...

Sheet 2024 CHF
A1: SFH
A2: Measure | B2: Unit | C2: CH | D2: ZH | E2: BE | F2: LU | G2: UR | H2: SZ | I2: OW | J2: NW | K2: GL | L2: ZG | M2: FR | N2: SO | O2: BS | P2: BL | Q2: SH | R2: AR | S2: AI | T2: SG | U2: GR | V2: AG | W2: TG | X2: TI | Y2: VD | Z2: VS | AA2: NE | AB2: GE | AC2: JU
A3: Wood/pellet with daily tank | B3: CHF | C3: 997973.5 | D3: 0 | E3: 0 | F3: 29000 | G3: 14000 | H3: 25000 | I3: 12000 | J3: 0 | K3: 28000 | L3: 0 | M3: 46000 | N3: 18000 | O3: 0 | P3: 39973.5 | Q3: 42000 | R3: 36500 | S3: 0 | T3: 20000 | U3: 360000 | V3: 42000 | W3: 73000 | X3: 48500 | Y3: 94000 | Z3: 55000 | AA3: 0 | AB3: 0 | AC3: 15000
A4: Automatic wood heating, heat output ≤ 70 kW | B4: CHF | C4: 3606320 | D4: 0 | E4: 919336 | F4: 66860 | G4: 6000 | H4: 0 | I4: 0 | J4: 0 | K4: 34750 | L4: 0 | M4: 67444 | N4: 176465 | O4: 78810 | P4: 94265 | Q4: 64000 | R4: 7500 | S4: 4300 | T4: 0 | U4: 461320 | V4: 60779 | W4: 104975 | X4: 98927 | Y4: 825450 | Z4: 183974 | AA4: 287745 | AB4: 0 | AC4: 63420
A5: Automatic wood heating, heat output > 70 kW | B5: CHF | C5: 10471 | D5: 0 | E5: 0 | F5: 0 | G5: 0 | H5: 0 | I5: 0 | J5: 0 | K5: 0 | L5: 0 | M5: 0 | N5: 0 | O5: 0 | P5: 7200 | Q5: 0 | R5: 0 | S5: 0 | T5: 0 | U5: 0 | V5: 0 | W5: 0 | X5: 0 | Y5: 3271 | Z5: 0 | AA5: 0 | AB5: 0 | AC5: 0
A6: HP air-water | B6: CHF | C6: 83829105 | D6: 7990829 | E6: 11426800 | F6: 1876678 | G6: 210280 | H6: 1006332 | I6: 33000 | J6: 71326 | K6: 591260 | L6: 544000 | M6: 4038898 | N6: 3723247 | O6: 1821209 | P6: 7615960 | Q6: 566145 | R6: 905432 | S6: 56808 | T6: 2243735 | U6: 2206244 | V6: 4781476 | W6: 2306880 | X6: 9098945 | Y6: 6863349 | Z6: 6956807 | AA6: 1960974 | AB6: 4420119 | AC6: 512372
A7: HP electric (brine/water, water/water) | B7: CHF | C7: 48448164 | D7: 12422233 | E7: 3173100 | F7: 3050182 | G7: 8000 | H7: 422619 | I7: 36000 | J7: 5488 | K7: 28750 | L7: 2558731 | M7: 1993815 | N7: 1260166.5 | O7: 5749851 | P7: 928259 | Q7: 311800 | R7: 271953 | S7: 54546 | T7: 2006490 | U7: 1766185 | V7: 2147142 | W7: 3196345 | X7: 273046 | Y7: 6208118 | Z7: 374148 | AA7: 78324 | AB7: 96948 | AC7: 25925
A8: DH | B8: CHF | C8: 7818812 | D8: 1364054 | E8: 1518897 | F8: 439749 | G8: 12540 | H8: 528852 | I8: 26000 | J8: 30875 | K8: 49438 | L8: 17400 | M8: 367992 | N8: 180430 | O8: 391539 | P8: 91090 | Q8: 603755 | R8: 101370 | S8: 8198 | T8: 30000 | U8: 310813 | V8: 210131 | W8: 534238 | X8: 359900 | Y8: 150538 | Z8: 245686 | AA8: 241180 | AB8: 4147 | AC8: 0
A9: ST | B9: CHF | C9: 1888543.9 | D9: 52365 | E9: 157800 | F9: 115770.9 | G9: 11600 | H9: 13996 | I9: 0 | J9: 5645 | K9: 43605 | L9: 0 | M9: 37510 | N9: 51141 | O9: 9112 | P9: 31982 | Q9: 5052 | R9: 15090 | S9: 3783 | T9: 0 | U9: 124822 | V9: 44086 | W9: 57725 | X9: 66572 | Y9: 864038 | Z9: 46096 | AA9: 38153 | AB9: 44233 | AC9: 48367
A10: Ventilation and heat recovery | B10: CHF | C10: 40300 | D10: 0 | E10: 3000 | F10: 0 | G10: 0 | H10: 0 | I10: 0 | J10: 0 | K10: 0 | L10: 0 | M10: 0 | N10: 0 | O10: 4800 | P10: 0 | Q10: 7000 | R10: 0 | S10: 0 | T10: 0 | U10: 10000 | V10: 0 | W10: 3500 | X10: 0 | Y10: 12000 | Z10: 0 | AA10: 0 | AB10: 0 | AC10: 0
A12: MFH
A13: Measure | B13: Unit | C13: CH | D13: ZH | E13: BE | F13: LU | G13: UR | H13: SZ | I13: OW | J13: NW | K13: GL | L13: ZG | M13: FR | N13: SO | O13: BS | P13: BL | Q13: SH | R13: AR | S13: AI | T13: SG | U13: GR | V13: AG | W13: TG | X13: TI | Y13: VD | Z13: VS | AA13: NE | AB13: GE | AC13: JU
A14: Wood/pellet with daily tank | B14: CHF | C14: 238968 | D14: 0 | E14: 0 | F14: 15000 | G14: 4000 | H14: 20000 | I14: 27000 | J14: 0 | K14: 0 | L14: 0 | M14: 0 | N14: 6000 | O14: 0 | P14: 5968 | Q14: 14000 | R14: 5500 | S14: 0 | T14: 0 | U14: 90000 | V14: 9000 | W14: 37500 | X14: 0 | Y14: 0 | Z14: 0 | AA14: 0 | AB14: 0 | AC14: 5000
A15: Automatic wood heating, heat output ≤ 70 kW | B15: CHF | C15: 2430560 | D15: 0 | E15: 243138 | F15: 90570 | G15: 14300 | H15: 13350 | I15: 0 | J15: 13830 | K15: 25710 | L15: 0 | M15: 33483 | N15: 88383 | O15: 100200 | P15: 49690 | Q15: 44880 | R15: 13271 | S15: 5000 | T15: 0 | U15: 831640 | V15: 17095 | W15: 146900 | X15: 35900 | Y15: 335530 | Z15: 59230 | AA15: 222530 | AB15: 0 | AC15: 45930
A16: Automatic wood heating, heat output > 70 kW | B16: CHF | C16: 1256385 | D16: 0 | E16: 64620 | F16: 24000 | G16: 0 | H16: 33000 | I16: 0 | J16: 0 | K16: 0 | L16: 102000 | M16: 0 | N16: 0 | O16: 0 | P16: 76755 | Q16: 25750 | R16: 0 | S16: 0 | T16: 0 | U16: 567251 | V16: 0 | W16: 71500 | X16: 38200 | Y16: 28640 | Z16: 187499 | AA16: 37170 | AB16: 0 | AC16: 0
A17: HP air-water | B17: CHF | C17: 14742693 | D17: 1614685 | E17: 2324550 | F17: 518608 | G17: 37400 | H17: 538374 | I17: 3000 | J17: 108559 | K17: 50950 | L17: 278420 | M17: 480954 | N17: 670106 | O17: 401325 | P17: 955301 | Q17: 155507 | R17: 143854 | S17: 2296 | T17: 94314 | U17: 1659344 | V17: 659172 | W17: 522248 | X17: 851959 | Y17: 563245 | Z17: 1318659 | AA17: 294557 | AB17: 402520 | AC17: 92786
A18: HP electric (brine/water, water/water) | B18: CHF | C18: 28567308 | D18: 7300670 | E18: 1366260 | F18: 2993933 | G18: 78440 | H18: 399560 | I18: 22860 | J18: 166913 | K18: 71363 | L18: 4091400 | M18: 713644 | N18: 660489.5 | O18: 780665 | P18: 512930 | Q18: 228958 | R18: 72798 | S18: 9690 | T18: 586546 | U18: 3796380 | V18: 1225994 | W18: 1552165 | X18: 212386 | Y18: 1010870 | Z18: 688858 | AA18: 17865 | AB18: 0 | AC18: 5670
A19: DH | B19: CHF | C19: 19904716 | D19: 2931412 | E19: 2114179 | F19: 1078916 | G19: 97180 | H19: 1173130 | I19: 72500 | J19: 336355 | K19: 91486 | L19: 956110 | M19: 774264 | N19: 374951 | O19: 2518509 | P19: 387440 | Q19: 933614 | R19: 93066 | S19: 4250 | T19: 15000 | U19: 2018133 | V19: 769703 | W19: 645860 | X19: 184000 | Y19: 946109 | Z19: 1131546 | AA19: 257003 | AB19: 0 | AC19: 0
A20: ST | B20: CHF | C20: 1243237.1 | D20: 28948 | E20: 158820 | F20: 109236.1 | G20: 0 | H20: 35406 | I20: 0 | J20: 0 | K20: 9322 | L20: 0 | M20: 19783 | N20: 5478 | O20: 6612 | P20: 0 | Q20: 11646 | R20: 15185 | S20: 0 | T20: 20000 | U20: 144827 | V20: 59945 | W20: 5604 | X20: 39097 | Y20: 370594 | Z20: 4886 | AA20: 38584 | AB20: 136437 | AC20: 22827
A21: Ventilation and heat recovery | B21: CHF | C21: 750150 | D21: 0 | E21: 334000 | F21: 0 | G21: 0 | H21: 0 | I21: 0 | J21: 0 | K21: 0 | L21: 0 | M21: 0 | N21: 0 | O21: 9600 | P21: 0 | Q21: 0 | R21: 0 | S21: 0 | T21: 0 | U21: 80000 | V21: 0 | W21: 0 | X21: 0 | Y21: 69600 | Z21: 0 | AA21: 0 | AB21: 256950 | AC21: 0
A23: Non Res
A24: Measure | B24: Unit | C24: CH | D24: ZH | E24: BE | F24: LU | G24: UR | H24: SZ | I24: OW | J24: NW | K24: GL | L24: ZG | M24: FR | N24: SO | O24: BS | P24: BL | Q24: SH | R24: AR | S24: AI | T24: SG | U24: GR | V24: AG | W24: TG | X24: TI | Y24: VD | Z24: VS | AA24: NE | AB24: GE | AC24: JU
A25: Wood/pellet with daily tank | B25: CHF | C25: 35000 | D25: 0 | E25: 0 | F25: 0 | G25: 0 | H25: 0 | I25: 0 | J25: 0 | K25: 6000 | L25: 0 | M25: 0 | N25: 0 | O25: 0 | P25: 0 | Q25: 0 | R25: 0 | S25: 0 | T25: 0 | U25: 20000 | V25: 0 | W25: 6000 | X25: 3000 | Y25: 0 | Z25: 0 | AA25: 0 | AB25: 0 | AC25: 0
A26: Automatic wood heating, heat output ≤ 70 kW | B26: CHF | C26: 430317 | D26: 0 | E26: 63120 | F26: 8000 | G26: 0 | H26: 0 | I26: 0 | J26: 5600 | K26: 7300 | L26: 0 | M26: 10923 | N26: 51776 | O26: 0 | P26: 17900 | Q26: 0 | R26: 24683 | S26: 0 | T26: 0 | U26: 80940 | V26: 4600 | W26: 50600 | X26: 0 | Y26: 18170 | Z26: 77505 | AA26: 9200 | AB26: 0 | AC26: 0
A27: Automatic wood heating, heat output > 70 kW | B27: CHF | C27: 613432 | D27: 0 | E27: 35100 | F27: 55395 | G27: 0 | H27: 0 | I27: 0 | J27: 0 | K27: 0 | L27: 0 | M27: 14500 | N27: 0 | O27: 0 | P27: 29700 | Q27: 0 | R27: 0 | S27: 0 | T27: 5940 | U27: 75120 | V27: 0 | W27: 77500 | X27: 0 | Y27: 36000 | Z27: 284177 | AA27: 0 | AB27: 0 | AC27: 0
A28: HP air-water | B28: CHF | C28: 2631668 | D28: 221109 | E28: 193000 | F28: 52820 | G28: 23000 | H28: 44358 | I28: 0 | J28: 5750 | K28: 10750 | L28: 59500 | M28: 42275 | N28: 115313 | O28: 14125 | P28: 127754 | Q28: 94640 | R28: 9350 | S28: 4996 | T28: 11620 | U28: 364965 | V28: 225524 | W28: 326443 | X28: 292479 | Y28: 69876 | Z28: 212260 | AA28: 21707 | AB28: 37596 | AC28: 50458
A29: HP electric (brine/water, water/water) | B29: CHF | C29: 3480161 | D29: 385884 | E29: 142220 | F29: 209454 | G29: 0 | H29: 104870 | I29: 0 | J29: 19788 | K29: 10175 | L29: 0 | M29: 18180 | N29: 258743 | O29: 36525 | P29: 25820 | Q29: 125931 | R29: 14014 | S29: 6900 | T29: 87680 | U29: 328130 | V29: 149491 | W29: 696825 | X29: 207288 | Y29: 173010 | Z29: 332433 | AA29: 0 | AB29: 146800 | AC29: 0
A30: DH | B30: CHF | C30: 4571918 | D30: 354787 | E30: 412735 | F30: 257124 | G30: 35440 | H30: 468105 | I30: 0 | J30: 52838 | K30: 70039 | L30: 400206 | M30: 116486 | N30: 95298 | O30: 403886 | P30: 160785 | Q30: 337517 | R30: 0 | S30: 0 | T30: 0 | U30: 281897 | V30: 194920 | W30: 288356 | X30: 107750 | Y30: 227343 | Z30: 273806 | AA30: 4600 | AB30: 28000 | AC30: 0
A31: ST | B31: CHF | C31: 220824 | D31: 0 | E31: 38900 | F31: 78970 | G31: 0 | H31: 0 | I31: 0 | J31: 0 | K31: 0 | L31: 0 | M31: 3850 | N31: 0 | O31: 0 | P31: 0 | Q31: 0 | R31: 0 | S31: 0 | T31: 0 | U31: 6703 | V31: 0 | W31: 0 | X31: 11417 | Y31: 5630 | Z31: 6764 | AA31: 0 | AB31: 68590 | AC31: 0
A32: Ventilation and heat recovery | B32: CHF | C32: 0 | D32: 0 | E32: 0 | F32: 0 | G32: 0 | H32: 0 | I32: 0 | J32: 0 | K32: 0 | L32: 0 | M32: 0 | N32: 0 | O32: 0 | P32: 0 | Q32: 0 | R32: 0 | S32: 0 | T32: 0 | U32: 0 | V32: 0 | W32: 0 | X32: 0 | Y32: 0 | Z32: 0 | AA32: 0 | AB32: 0 | AC32: 0
A34: SFH
A35: Measure | B35: Index | D35: AG | E35: AI | F35: AR | G35: BE | H35: BL | I35: BS | J35: FR | K35: GE | L35: GL | M35: GR | N35: JU | O35: LU | P35: NE | Q35: NW | R35: OW | S35: SG | T35: SH | U35: SO | V35: SZ | W35: TG | X35: TI | Y35: UR | Z35: VD | AA35: VS | AB35: ZG | AC35: ZH
A36: Wood/pellet with daily tank | B36: 2 | D36: =HLOOKUP(D$35,$D$2:$AC$10,$B36,FALSE) -> 42000 | E36: =HLOOKUP(E$35,$D$2:$AC$10,$B36,FALSE) -> 0 | F36: =HLOOKUP(F$35,$D$2:$AC$10,$B36,FALSE) -> 36500 | G36: =HLOOKUP(G$35,$D$2:$AC$10,$B36,FALSE) -> 0 | H36: =HLOOKUP(H$35,$D$2:$AC$10,$B36,FALSE) -> 39973.5 | I36: =HLOOKUP(I$35,$D$2:$AC$10,$B36,FALSE) -> 0 | J36: =HLOOKUP(J$35,$D$2:$AC$10,$B36,FALSE) -> 46000 | K36: =HLOOKUP(K$35,$D$2:$AC$10,$B36,FALSE) -> 0 | ... AC36: =HLOOKUP(AC$35,$D$2:$AC$10,$B36,FALSE) -> 0
A37: Automatic wood heating, heat output ≤ 70 kW | B37: 3 | D37: =HLOOKUP(D$35,$D$2:$AC$10,$B37,FALSE) -> 60779 | E37: =HLOOKUP(E$35,$D$2:$AC$10,$B37,FALSE) -> 4300 | F37: =HLOOKUP(F$35,$D$2:$AC$10,$B37,FALSE) -> 7500 | G37: =HLOOKUP(G$35,$D$2:$AC$10,$B37,FALSE) -> 919336 | H37: =HLOOKUP(H$35,$D$2:$AC$10,$B37,FALSE) -> 94265 | I37: =HLOOKUP(I$35,$D$2:$AC$10,$B37,FALSE) -> 78810 | J37: =HLOOKUP(J$35,$D$2:$AC$10,$B37,FALSE) -> 67444 | K37: =HLOOKUP(K$35,$D$2:$AC$10,$B37,FALSE) -> 0 | ... AC37: =HLOOKUP(AC$35,$D$2:$AC$10,$B37,FALSE) -> 0
A38: Automatic wood heating, heat output > 70 kW | B38: 4 | D38: =HLOOKUP(D$35,$D$2:$AC$10,$B38,FALSE) -> 0 | E38: =HLOOKUP(E$35,$D$2:$AC$10,$B38,FALSE) -> 0 | F38: =HLOOKUP(F$35,$D$2:$AC$10,$B38,FALSE) -> 0 | G38: =HLOOKUP(G$35,$D$2:$AC$10,$B38,FALSE) -> 0 | H38: =HLOOKUP(H$35,$D$2:$AC$10,$B38,FALSE) -> 7200 | I38: =HLOOKUP(I$35,$D$2:$AC$10,$B38,FALSE) -> 0 | J38: =HLOOKUP(J$35,$D$2:$AC$10,$B38,FALSE) -> 0 | K38: =HLOOKUP(K$35,$D$2:$AC$10,$B38,FALSE) -> 0 | ... AC38: =HLOOKUP(AC$35,$D$2:$AC$10,$B38,FALSE) -> 0
A39: HP air-water | B39: 5 | D39: =HLOOKUP(D$35,$D$2:$AC$10,$B39,FALSE) -> 4781476 | E39: =HLOOKUP(E$35,$D$2:$AC$10,$B39,FALSE) -> 56808 | F39: =HLOOKUP(F$35,$D$2:$AC$10,$B39,FALSE) -> 905432 | G39: =HLOOKUP(G$35,$D$2:$AC$10,$B39,FALSE) -> 11426800 | H39: =HLOOKUP(H$35,$D$2:$AC$10,$B39,FALSE) -> 7615960 | I39: =HLOOKUP(I$35,$D$2:$AC$10,$B39,FALSE) -> 1821209 | J39: =HLOOKUP(J$35,$D$2:$AC$10,$B39,FALSE) -> 4038898 | K39: =HLOOKUP(K$35,$D$2:$AC$10,$B39,FALSE) -> 4420119 | ... AC39: =HLOOKUP(AC$35,$D$2:$AC$10,$B39,FALSE) -> 7990829
A40: HP electric (brine/water, water/water) | B40: 6 | D40: =HLOOKUP(D$35,$D$2:$AC$10,$B40,FALSE) -> 2147142 | E40: =HLOOKUP(E$35,$D$2:$AC$10,$B40,FALSE) -> 54546 | F40: =HLOOKUP(F$35,$D$2:$AC$10,$B40,FALSE) -> 271953 | G40: =HLOOKUP(G$35,$D$2:$AC$10,$B40,FALSE) -> 3173100 | H40: =HLOOKUP(H$35,$D$2:$AC$10,$B40,FALSE) -> 928259 | I40: =HLOOKUP(I$35,$D$2:$AC$10,$B40,FALSE) -> 5749851 | J40: =HLOOKUP(J$35,$D$2:$AC$10,$B40,FALSE) -> 1993815 | K40: =HLOOKUP(K$35,$D$2:$AC$10,$B40,FALSE) -> 96948 | ... AC40: =HLOOKUP(AC$35,$D$2:$AC$10,$B40,FALSE) -> 12422233
A41: DH | B41: 7 | D41: =HLOOKUP(D$35,$D$2:$AC$10,$B41,FALSE) -> 210131 | E41: =HLOOKUP(E$35,$D$2:$AC$10,$B41,FALSE) -> 8198 | F41: =HLOOKUP(F$35,$D$2:$AC$10,$B41,FALSE) -> 101370 | G41: =HLOOKUP(G$35,$D$2:$AC$10,$B41,FALSE) -> 1518897 | H41: =HLOOKUP(H$35,$D$2:$AC$10,$B41,FALSE) -> 91090 | I41: =HLOOKUP(I$35,$D$2:$AC$10,$B41,FALSE) -> 391539 | J41: =HLOOKUP(J$35,$D$2:$AC$10,$B41,FALSE) -> 367992 | K41: =HLOOKUP(K$35,$D$2:$AC$10,$B41,FALSE) -> 4147 | ... AC41: =HLOOKUP(AC$35,$D$2:$AC$10,$B41,FALSE) -> 1364054
A42: ST | B42: 8 | D42: =HLOOKUP(D$35,$D$2:$AC$10,$B42,FALSE) -> 44086 | E42: =HLOOKUP(E$35,$D$2:$AC$10,$B42,FALSE) -> 3783 | F42: =HLOOKUP(F$35,$D$2:$AC$10,$B42,FALSE) -> 15090 | G42: =HLOOKUP(G$35,$D$2:$AC$10,$B42,FALSE) -> 157800 | H42: =HLOOKUP(H$35,$D$2:$AC$10,$B42,FALSE) -> 31982 | I42: =HLOOKUP(I$35,$D$2:$AC$10,$B42,FALSE) -> 9112 | J42: =HLOOKUP(J$35,$D$2:$AC$10,$B42,FALSE) -> 37510 | K42: =HLOOKUP(K$35,$D$2:$AC$10,$B42,FALSE) -> 44233 | ... AC42: =HLOOKUP(AC$35,$D$2:$AC$10,$B42,FALSE) -> 52365
A43: Ventilation and heat recovery | B43: 9 | D43: =HLOOKUP(D$35,$D$2:$AC$10,$B43,FALSE) -> 0 | E43: =HLOOKUP(E$35,$D$2:$AC$10,$B43,FALSE) -> 0 | F43: =HLOOKUP(F$35,$D$2:$AC$10,$B43,FALSE) -> 0 | G43: =HLOOKUP(G$35,$D$2:$AC$10,$B43,FALSE) -> 3000 | H43: =HLOOKUP(H$35,$D$2:$AC$10,$B43,FALSE) -> 0 | I43: =HLOOKUP(I$35,$D$2:$AC$10,$B43,FALSE) -> 4800 | J43: =HLOOKUP(J$35,$D$2:$AC$10,$B43,FALSE) -> 0 | K43: =HLOOKUP(K$35,$D$2:$AC$10,$B43,FALSE) -> 0 | ... AC43: =HLOOKUP(AC$35,$D$2:$AC$10,$B43,FALSE) -> 0
...

Sheet 2023
A1: SFH
A2: Measure | B2: Unit | C2: CH | D2: ZH | E2: BE | F2: LU | G2: UR | H2: SZ | I2: OW | J2: NW | K2: GL | L2: ZG | M2: FR | N2: SO | O2: BS | P2: BL | Q2: SH | R2: AR | S2: AI | T2: SG | U2: GR | V2: AG | W2: TG | X2: TI | Y2: VD | Z2: VS | AA2: NE | AB2: GE | AC2: JU
A3: Wood/pellet with daily tank | B3: - | C3: 148 | D3: 0 | E3: 0 | F3: 3 | G3: 4 | H3: 5 | I3: 6 | J3: 0 | K3: 6 | L3: 0 | M3: 11 | N3: 3 | O3: 0 | P3: 7 | Q3: 4 | R3: 9 | S3: 0 | T3: 3 | U3: 20 | V3: 17 | W3: 5 | X3: 18 | Y3: 16 | Z3: 8 | AA3: 0 | AB3: 0 | AC3: 3
A4: Automatic wood heating, heat output ≤ 70 kW | B4: - | C4: 601 | D4: 0 | E4: 186 | F4: 15 | G4: 4 | H4: 5 | I4: 0 | J4: 2 | K4: 5 | L4: 1 | M4: 24 | N4: 59 | O4: 5 | P4: 29 | Q4: 8 | R4: 7 | S4: 0 | T4: 0 | U4: 32 | V4: 15 | W4: 15 | X4: 12 | Y4: 110 | Z4: 28 | AA4: 28 | AB4: 0 | AC4: 11
A5: Automatic wood heating, heat output > 70 kW | B5: - | C5: 2 | D5: 0 | E5: 1 | F5: 0 | G5: 0 | H5: 0 | I5: 0 | J5: 0 | K5: 0 | L5: 0 | M5: 0 | N5: 0 | O5: 0 | P5: 0 | Q5: 0 | R5: 0 | S5: 0 | T5: 0 | U5: 1 | V5: 0 | W5: 0 | X5: 0 | Y5: 0 | Z5: 0 | AA5: 0 | AB5: 0 | AC5: 0
A6: HP air-water | B6: - | C6: 15885 | D6: 1479 | E6: 2200 | F6: 429 | G6: 10 | H6: 243 | I6: 10 | J6: 27 | K6: 174 | L6: 85 | M6: 804 | N6: 1194 | O6: 165 | P6: 1158 | Q6: 191 | R6: 227 | S6: 20 | T6: 1218 | U6: 390 | V6: 1548 | W6: 839 | X6: 983 | Y6: 867 | Z6: 756 | AA6: 364 | AB6: 449 | AC6: 55
A7: HP electric (brine/water, water/water) | B7: - | C7: 4081 | D7: 979 | E7: 371 | F7: 329 | G7: 3 | H7: 28 | I7: 3 | J7: 4 | K7: 9 | L7: 93 | M7: 263 | N7: 150 | O7: 110 | P7: 83 | Q7: 33 | R7: 41 | S7: 15 | T7: 486 | U7: 113 | V7: 250 | W7: 359 | X7: 5 | Y7: 305 | Z7: 23 | AA7: 13 | AB7: 9 | AC7: 4
A8: DH | B8: - | C8: 984 | D8: 127 | E8: 272 | F8: 31 | G8: 8 | H8: 86 | I8: 11 | J8: 4 | K8: 19 | L8: 2 | M8: 95 | N8: 25 | O8: 57 | P8: 19 | Q8: 67 | R8: 17 | S8: 0 | T8: 2 | U8: 11 | V8: 36 | W8: 32 | X8: 14 | Y8: 22 | Z8: 10 | AA8: 15 | AB8: 0 | AC8: 2
A9: ST | B9: - | C9: 384 | D9: 7 | E9: 48 | F9: 15 | G9: 2 | H9: 3 | I9: 0 | J9: 0 | K9: 2 | L9: 0 | M9: 14 | N9: 12 | O9: 3 | P9: 14 | Q9: 0 | R9: 6 | S9: 1 | T9: 5 | U9: 28 | V9: 11 | W9: 10 | X9: 20 | Y9: 125 | Z9: 14 | AA9: 21 | AB9: 12 | AC9: 11
A10: Ventilation and heat recovery | B10: - | C10: 10 | D10: 0 | E10: 2 | F10: 0 | G10: 0 | H10: 0 | I10: 0 | J10: 0 | K10: 0 | L10: 0 | M10: 0 | N10: 0 | O10: 0 | P10: 0 | Q10: 0 | R10: 0 | S10: 0 | T10: 0 | U10: 2 | V10: 0 | W10: 4 | X10: 0 | Y10: 1 | Z10: 0 | AA10: 0 | AB10: 1 | AC10: 0
A12: MFH
